Workbook

Sheet BioBlitz Surveys - Wetland
B1: Identification Information | Informations d'identification | F1: Prevalence Across Sites | Prévalence parmi les sites | G1: Plot 1 | L1: Plot 2 | Q1: Plot 3 | V1: Plot 4 | AA1: Plot 5
A2: Obs. no. | B2: Latin name | Nom latin | C2: Common name | Nom commun | D2: Taxon type | Type de taxon [Dropdown menu] | E2: Group Colour | Couleur de groupe | F2: Do you see this organism yet on the list? | Est-ce que vous voyez déjà cet organisme sur la liste? (Yes or No) | G2: Plot 1 Presence | H2: Plot 1 Cover | I2: DO NOT CHANGE Cover proportion | J2: Other remarks | K2: Height (cm) | L2: Plot 2 Presence | M2: Plot 2 Cover | N2: DO NOT CHANGE Cover proportion | O2: Other remarks | P2: Height (cm) | Q2: Plot 3 Presence | R2: Plot 3 Cover | S2: DO NOT CHANGE Cover proportion | T2: Other remarks | U2: Height (cm) | V2: Plot 4 Presence | W2: Plot 4 Cover | X2: DO NOT CHANGE Cover proportion | Y2: Other remarks | Z2: Height (cm) | AA2: Plot 5 Presence | AB2: Plot 5 Cover | AC2: DO NOT CHANGE Cover proportion | AD2: Other remarks | AE2: Height (cm)
A3: EXAMPLE | B3: Larix laricina | C3: Tamarack | D3: Evergreen tree | Arbre sempervirent | E3: Purple | F3: Yes | G3: Yes | H3: 4 | I3: =IF(H3 = 5, 1, IF(H3 = 4, 0.75, IF(H3 = 3, 0.5, IF(H3 = 2, 0.25, IF(H3 = 1, 0.05, IF(H3 = "<1%", 0.01, IF(H3 = "", ""))))))) -> 0.75 | J3: 1 | K3: 6 | L3: Yes | M3: 3 | N3: =IF(M3 = 5, 1, IF(M3 = 4, 0.75, IF(M3 = 3, 0.5, IF(M3 = 2, 0.25, IF(M3 = 1, 0.05, IF(M3 = "<1%", 0.01, IF(M3 = "", ""))))))) -> 0.5 | O3: 1 | P3: 6 | Q3: No | S3: =IF(R3 = 5, 1, IF(R3 = 4, 0.75, IF(R3 = 3, 0.5, IF(R3 = 2, 0.25, IF(R3 = 1, 0.05, IF(R3 = "<1%", 0.01, IF(R3 = "", ""))))))) | V3: No | X3: =IF(W3 = 5, 1, IF(W3 = 4, 0.75, IF(W3 = 3, 0.5, IF(W3 = 2, 0.25, IF(W3 = 1, 0.05, IF(W3 = "<1%", 0.01, IF(W3 = "", ""))))))) | AA3: Yes | AB3: 5 | AC3: =IF(AB3 = 5, 1, IF(AB3 = 4, 0.75, IF(AB3 = 3, 0.5, IF(AB3 = 2, 0.25, IF(AB3 = 1, 0.05, IF(AB3 = "<1%", 0.01, IF(AB3 = "", ""))))))) -> 1 | AD3: 1 | AE3: 6
A4: 1 | B4: Bidens discoidea | C4: Swamp Beggarticks | D4: Aquatic plant | Plante aquatique | E4: Pink | F4: Yes | G4: Yes | H4: 4 | I4: =IF(H4 = 5, 1, IF(H4 = 4, 0.75, IF(H4 = 3, 0.5, IF(H4 = 2, 0.25, IF(H4 = 1, 0.05, IF(H4 = "<1%", 0.01, IF(H4 = "", ""))))))) -> 0.75 | K4: 3 | L4: Yes | M4: 1 | N4: =IF(M4 = 5, 1, IF(M4 = 4, 0.75, IF(M4 = 3, 0.5, IF(M4 = 2, 0.25, IF(M4 = 1, 0.05, IF(M4 = "<1%", 0.01, IF(M4 = "", ""))))))) -> 0.05 | P4: 3 | Q4: Yes | R4: 1 | S4: =IF(R4 = 5, 1, IF(R4 = 4, 0.75, IF(R4 = 3, 0.5, IF(R4 = 2, 0.25, IF(R4 = 1, 0.05, IF(R4 = "<1%", 0.01, IF(R4 = "", ""))))))) -> 0.05 | U4: 3 | V4: Yes | W4: 1 | X4: =IF(W4 = 5, 1, IF(W4 = 4, 0.75, IF(W4 = 3, 0.5, IF(W4 = 2, 0.25, IF(W4 = 1, 0.05, IF(W4 = "<1%", 0.01, IF(W4 = "", ""))))))) -> 0.05 | Z4: 3 | AA4: No | AC4: =IF(AB4 = 5, 1, IF(AB4 = 4, 0.75, IF(AB4 = 3, 0.5, IF(AB4 = 2, 0.25, IF(AB4 = 1, 0.05, IF(AB4 = "<1%", 0.01, IF(AB4 = "", "")))))))
A5: 2 | B5: Chamaedaphne calyculata | C5: Leather leaf | D5: Shrub | Arbuste | E5: Pink | F5: Yes | G5: Yes | H5: 2 | I5: =IF(H5 = 5, 1, IF(H5 = 4, 0.75, IF(H5 = 3, 0.5, IF(H5 = 2, 0.25, IF(H5 = 1, 0.05, IF(H5 = "<1%", 0.01, IF(H5 = "", ""))))))) -> 0.25 | K5: 2 | L5: Yes | M5: 2 | N5: =IF(M5 = 5, 1, IF(M5 = 4, 0.75, IF(M5 = 3, 0.5, IF(M5 = 2, 0.25, IF(M5 = 1, 0.05, IF(M5 = "<1%", 0.01, IF(M5 = "", ""))))))) -> 0.25 | P5: 2 | Q5: Yes | R5: 2 | S5: =IF(R5 = 5, 1, IF(R5 = 4, 0.75, IF(R5 = 3, 0.5, IF(R5 = 2, 0.25, IF(R5 = 1, 0.05, IF(R5 = "<1%", 0.01, IF(R5 = "", ""))))))) -> 0.25 | U5: 2 | V5: No | X5: =IF(W5 = 5, 1, IF(W5 = 4, 0.75, IF(W5 = 3, 0.5, IF(W5 = 2, 0.25, IF(W5 = 1, 0.05, IF(W5 = "<1%", 0.01, IF(W5 = "", ""))))))) | Z5: 2 | AA5: Yes | AB5: 2 | AC5: =IF(AB5 = 5, 1, IF(AB5 = 4, 0.75, IF(AB5 = 3, 0.5, IF(AB5 = 2, 0.25, IF(AB5 = 1, 0.05, IF(AB5 = "<1%", 0.01, IF(AB5 = "", ""))))))) -> 0.25 | AE5: 2
A6: 3 | B6: Dulichium arundinaceum | C6: Three-way sedge | D6: Grass or Sedge | Graminée | E6: Pink | F6: Yes | G6: No | I6: =IF(H6 = 5, 1, IF(H6 = 4, 0.75, IF(H6 = 3, 0.5, IF(H6 = 2, 0.25, IF(H6 = 1, 0.05, IF(H6 = "<1%", 0.01, IF(H6 = "", ""))))))) | K6: 2 | L6: Yes | M6: 2 | N6: =IF(M6 = 5, 1, IF(M6 = 4, 0.75, IF(M6 = 3, 0.5, IF(M6 = 2, 0.25, IF(M6 = 1, 0.05, IF(M6 = "<1%", 0.01, IF(M6 = "", ""))))))) -> 0.25 | P6: 2 | Q6: Yes | R6: 2 | S6: =IF(R6 = 5, 1, IF(R6 = 4, 0.75, IF(R6 = 3, 0.5, IF(R6 = 2, 0.25, IF(R6 = 1, 0.05, IF(R6 = "<1%", 0.01, IF(R6 = "", ""))))))) -> 0.25 | U6: 2 | V6: Yes | W6: 2 | X6: =IF(W6 = 5, 1, IF(W6 = 4, 0.75, IF(W6 = 3, 0.5, IF(W6 = 2, 0.25, IF(W6 = 1, 0.05, IF(W6 = "<1%", 0.01, IF(W6 = "", ""))))))) -> 0.25 | Z6: 2 | AA6: No | AC6: =IF(AB6 = 5, 1, IF(AB6 = 4, 0.75, IF(AB6 = 3, 0.5, IF(AB6 = 2, 0.25, IF(AB6 = 1, 0.05, IF(AB6 = "<1%", 0.01, IF(AB6 = "", ""))))))) | AE6: 2
A7: 4 | B7: Galium | C7: Bedstraws | D7: Shrub | Arbuste | E7: Pink | F7: Yes | G7: No | I7: =IF(H7 = 5, 1, IF(H7 = 4, 0.75, IF(H7 = 3, 0.5, IF(H7 = 2, 0.25, IF(H7 = 1, 0.05, IF(H7 = "<1%", 0.01, IF(H7 = "", ""))))))) | K7: 3 | L7: No | N7: =IF(M7 = 5, 1, IF(M7 = 4, 0.75, IF(M7 = 3, 0.5, IF(M7 = 2, 0.25, IF(M7 = 1, 0.05, IF(M7 = "<1%", 0.01, IF(M7 = "", ""))))))) | P7: 3 | Q7: No | S7: =IF(R7 = 5, 1, IF(R7 = 4, 0.75, IF(R7 = 3, 0.5, IF(R7 = 2, 0.25, IF(R7 = 1, 0.05, IF(R7 = "<1%", 0.01, IF(R7 = "", ""))))))) | U7: 3 | V7: Yes | W7: 1 | X7: =IF(W7 = 5, 1, IF(W7 = 4, 0.75, IF(W7 = 3, 0.5, IF(W7 = 2, 0.25, IF(W7 = 1, 0.05, IF(W7 = "<1%", 0.01, IF(W7 = "", ""))))))) -> 0.05 | Z7: 3 | AA7: Yes | AB7: 1 | AC7: =IF(AB7 = 5, 1, IF(AB7 = 4, 0.75, IF(AB7 = 3, 0.5, IF(AB7 = 2, 0.25, IF(AB7 = 1, 0.05, IF(AB7 = "<1%", 0.01, IF(AB7 = "", ""))))))) -> 0.05 | AE7: 3
A8: 5 | B8: Lycopus uniflorus | C8: Northern water-horehound | D8: Grass or Sedge | Graminée | E8: Pink | F8: Yes | G8: No | I8: =IF(H8 = 5, 1, IF(H8 = 4, 0.75, IF(H8 = 3, 0.5, IF(H8 = 2, 0.25, IF(H8 = 1, 0.05, IF(H8 = "<1%", 0.01, IF(H8 = "", ""))))))) | K8: 3 | L8: No | N8: =IF(M8 = 5, 1, IF(M8 = 4, 0.75, IF(M8 = 3, 0.5, IF(M8 = 2, 0.25, IF(M8 = 1, 0.05, IF(M8 = "<1%", 0.01, IF(M8 = "", ""))))))) | P8: 3 | Q8: No | S8: =IF(R8 = 5, 1, IF(R8 = 4, 0.75, IF(R8 = 3, 0.5, IF(R8 = 2, 0.25, IF(R8 = 1, 0.05, IF(R8 = "<1%", 0.01, IF(R8 = "", ""))))))) | U8: 3 | V8: Yes | W8: 1 | X8: =IF(W8 = 5, 1, IF(W8 = 4, 0.75, IF(W8 = 3, 0.5, IF(W8 = 2, 0.25, IF(W8 = 1, 0.05, IF(W8 = "<1%", 0.01, IF(W8 = "", ""))))))) -> 0.05 | Z8: 3 | AA8: Yes | AB8: 1 | AC8: =IF(AB8 = 5, 1, IF(AB8 = 4, 0.75, IF(AB8 = 3, 0.5, IF(AB8 = 2, 0.25, IF(AB8 = 1, 0.05, IF(AB8 = "<1%", 0.01, IF(AB8 = "", ""))))))) -> 0.05 | AE8: 3
A9: 6 | B9: Lythrum salicaria | C9: Purple loosestrife | D9: Grass or Sedge | Graminée | E9: Pink | F9: No | G9: No | I9: =IF(H9 = 5, 1, IF(H9 = 4, 0.75, IF(H9 = 3, 0.5, IF(H9 = 2, 0.25, IF(H9 = 1, 0.05, IF(H9 = "<1%", 0.01, IF(H9 = "", ""))))))) | K9: 3 | L9: No | N9: =IF(M9 = 5, 1, IF(M9 = 4, 0.75, IF(M9 = 3, 0.5, IF(M9 = 2, 0.25, IF(M9 = 1, 0.05, IF(M9 = "<1%", 0.01, IF(M9 = "", ""))))))) | P9: 3 | Q9: No | S9: =IF(R9 = 5, 1, IF(R9 = 4, 0.75, IF(R9 = 3, 0.5, IF(R9 = 2, 0.25, IF(R9 = 1, 0.05, IF(R9 = "<1%", 0.01, IF(R9 = "", ""))))))) | U9: 3 | V9: No | X9: =IF(W9 = 5, 1, IF(W9 = 4, 0.75, IF(W9 = 3, 0.5, IF(W9 = 2, 0.25, IF(W9 = 1, 0.05, IF(W9 = "<1%", 0.01, IF(W9 = "", ""))))))) | Z9: 3 | AA9: Yes | AB9: 1 | AC9: =IF(AB9 = 5, 1, IF(AB9 = 4, 0.75, IF(AB9 = 3, 0.5, IF(AB9 = 2, 0.25, IF(AB9 = 1, 0.05, IF(AB9 = "<1%", 0.01, IF(AB9 = "", ""))))))) -> 0.05 | AE9: 3
A10: 7 | B10: Onoclea sensibilis | C10: Sensitive fern | D10: Fern | Fougère | E10: Pink | F10: Yes | G10: Yes | H10: 1 | I10: =IF(H10 = 5, 1, IF(H10 = 4, 0.75, IF(H10 = 3, 0.5, IF(H10 = 2, 0.25, IF(H10 = 1, 0.05, IF(H10 = "<1%", 0.01, IF(H10 = "", ""))))))) -> 0.05 | K10: 2 | L10: Yes | M10: 1 | N10: =IF(M10 = 5, 1, IF(M10 = 4, 0.75, IF(M10 = 3, 0.5, IF(M10 = 2, 0.25, IF(M10 = 1, 0.05, IF(M10 = "<1%", 0.01, IF(M10 = "", ""))))))) -> 0.05 | P10: 2 | Q10: Yes | R10: 1 | S10: =IF(R10 = 5, 1, IF(R10 = 4, 0.75, IF(R10 = 3, 0.5, IF(R10 = 2, 0.25, IF(R10 = 1, 0.05, IF(R10 = "<1%", 0.01, IF(R10 = "", ""))))))) -> 0.05 | U10: 2 | V10: Yes | W10: 1 | X10: =IF(W10 = 5, 1, IF(W10 = 4, 0.75, IF(W10 = 3, 0.5, IF(W10 = 2, 0.25, IF(W10 = 1, 0.05, IF(W10 = "<1%", 0.01, IF(W10 = "", ""))))))) -> 0.05 | Z10: 2 | AA10: Yes | AB10: 1 | AC10: =IF(AB10 = 5, 1, IF(AB10 = 4, 0.75, IF(AB10 = 3, 0.5, IF(AB10 = 2, 0.25, IF(AB10 = 1, 0.05, IF(AB10 = "<1%", 0.01, IF(AB10 = "", ""))))))) -> 0.05 | AE10: 2
A11: 8 | B11: Phalaris canariensis | C11: Seed canary grass | D11: Grass or Sedge | Graminée | E11: Pink | F11: Yes | G11: No | I11: =IF(H11 = 5, 1, IF(H11 = 4, 0.75, IF(H11 = 3, 0.5, IF(H11 = 2, 0.25, IF(H11 = 1, 0.05, IF(H11 = "<1%", 0.01, IF(H11 = "", ""))))))) | K11: 2 | L11: No | M11: 2 | N11: =IF(M11 = 5, 1, IF(M11 = 4, 0.75, IF(M11 = 3, 0.5, IF(M11 = 2, 0.25, IF(M11 = 1, 0.05, IF(M11 = "<1%", 0.01, IF(M11 = "", ""))))))) -> 0.25 | P11: 2 | Q11: No | S11: =IF(R11 = 5, 1, IF(R11 = 4, 0.75, IF(R11 = 3, 0.5, IF(R11 = 2, 0.25, IF(R11 = 1, 0.05, IF(R11 = "<1%", 0.01, IF(R11 = "", ""))))))) | U11: 2 | V11: Yes | W11: 2 | X11: =IF(W11 = 5, 1, IF(W11 = 4, 0.75, IF(W11 = 3, 0.5, IF(W11 = 2, 0.25, IF(W11 = 1, 0.05, IF(W11 = "<1%", 0.01, IF(W11 = "", ""))))))) -> 0.25 | Z11: 2 | AA11: Yes | AB11: 2 | AC11: =IF(AB11 = 5, 1, IF(AB11 = 4, 0.75, IF(AB11 = 3, 0.5, IF(AB11 = 2, 0.25, IF(AB11 = 1, 0.05, IF(AB11 = "<1%", 0.01, IF(AB11 = "", ""))))))) -> 0.25 | AE11: 2
A12: 9 | B12: Spiraea tomentosa | C12: Steeplebush | D12: Shrub | Arbuste | E12: Pink | F12: Yes | G12: Yes | H12: 3 | I12: =IF(H12 = 5, 1, IF(H12 = 4, 0.75, IF(H12 = 3, 0.5, IF(H12 = 2, 0.25, IF(H12 = 1, 0.05, IF(H12 = "<1%", 0.01, IF(H12 = "", ""))))))) -> 0.5 | K12: 3 | L12: No | N12: =IF(M12 = 5, 1, IF(M12 = 4, 0.75, IF(M12 = 3, 0.5, IF(M12 = 2, 0.25, IF(M12 = 1, 0.05, IF(M12 = "<1%", 0.01, IF(M12 = "", ""))))))) | P12: 3 | Q12: No | S12: =IF(R12 = 5, 1, IF(R12 = 4, 0.75, IF(R12 = 3, 0.5, IF(R12 = 2, 0.25, IF(R12 = 1, 0.05, IF(R12 = "<1%", 0.01, IF(R12 = "", ""))))))) | U12: 3 | V12: Yes | W12: 1 | X12: =IF(W12 = 5, 1, IF(W12 = 4, 0.75, IF(W12 = 3, 0.5, IF(W12 = 2, 0.25, IF(W12 = 1, 0.05, IF(W12 = "<1%", 0.01, IF(W12 = "", ""))))))) -> 0.05 | Z12: 3 | AA12: Yes | AB12: 1 | AC12: =IF(AB12 = 5, 1, IF(AB12 = 4, 0.75, IF(AB12 = 3, 0.5, IF(AB12 = 2, 0.25, IF(AB12 = 1, 0.05, IF(AB12 = "<1%", 0.01, IF(AB12 = "", ""))))))) -> 0.05 | AE12: 3
A13: 10 | B13: Thelypteris palustris | C13: Marsh Fern | D13: Fern | Fougère | E13: Pink | F13: Yes | G13: No | I13: =IF(H13 = 5, 1, IF(H13 = 4, 0.75, IF(H13 = 3, 0.5, IF(H13 = 2, 0.25, IF(H13 = 1, 0.05, IF(H13 = "<1%", 0.01, IF(H13 = "", ""))))))) | K13: 3 | L13: No | N13: =IF(M13 = 5, 1, IF(M13 = 4, 0.75, IF(M13 = 3, 0.5, IF(M13 = 2, 0.25, IF(M13 = 1, 0.05, IF(M13 = "<1%", 0.01, IF(M13 = "", ""))))))) | P13: 3 | Q13: Yes | R13: 1 | S13: =IF(R13 = 5, 1, IF(R13 = 4, 0.75, IF(R13 = 3, 0.5, IF(R13 = 2, 0.25, IF(R13 = 1, 0.05, IF(R13 = "<1%", 0.01, IF(R13 = "", ""))))))) -> 0.05 | U13: 3 | V13: No | X13: =IF(W13 = 5, 1, IF(W13 = 4, 0.75, IF(W13 = 3, 0.5, IF(W13 = 2, 0.25, IF(W13 = 1, 0.05, IF(W13 = "<1%", 0.01, IF(W13 = "", ""))))))) | Z13: 3 | AA13: No | AC13: =IF(AB13 = 5, 1, IF(AB13 = 4, 0.75, IF(AB13 = 3, 0.5, IF(AB13 = 2, 0.25, IF(AB13 = 1, 0.05, IF(AB13 = "<1%", 0.01, IF(AB13 = "", ""))))))) | AE13: 3
A14: 11 | B14: Typha angustifolia | C14: Narrow-leaved Cattail | D14: Aquatic plant | Plante aquatique | E14: Pink | F14: Yes | G14: Yes | H14: 4 | I14: =IF(H14 = 5, 1, IF(H14 = 4, 0.75, IF(H14 = 3, 0.5, IF(H14 = 2, 0.25, IF(H14 = 1, 0.05, IF(H14 = "<1%", 0.01, IF(H14 = "", ""))))))) -> 0.75 | K14: 4 | L14: Yes | M14: 4 | N14: =IF(M14 = 5, 1, IF(M14 = 4, 0.75, IF(M14 = 3, 0.5, IF(M14 = 2, 0.25, IF(M14 = 1, 0.05, IF(M14 = "<1%", 0.01, IF(M14 = "", ""))))))) -> 0.75 | P14: 4 | Q14: Yes | R14: 4 | S14: =IF(R14 = 5, 1, IF(R14 = 4, 0.75, IF(R14 = 3, 0.5, IF(R14 = 2, 0.25, IF(R14 = 1, 0.05, IF(R14 = "<1%", 0.01, IF(R14 = "", ""))))))) -> 0.75 | U14: 4 | V14: Yes | W14: 4 | X14: =IF(W14 = 5, 1, IF(W14 = 4, 0.75, IF(W14 = 3, 0.5, IF(W14 = 2, 0.25, IF(W14 = 1, 0.05, IF(W14 = "<1%", 0.01, IF(W14 = "", ""))))))) -> 0.75 | Z14: 4 | AA14: Yes | AB14: 4 | AC14: =IF(AB14 = 5, 1, IF(AB14 = 4, 0.75, IF(AB14 = 3, 0.5, IF(AB14 = 2, 0.25, IF(AB14 = 1, 0.05, IF(AB14 = "<1%", 0.01, IF(AB14 = "", ""))))))) -> 0.75 | AE14: 4
A15: 12 | B15: Alnus sp. | C15: Alder | D15: Deciduous tree | Arbre décidu | E15: Purple | F15: No | G15: No | I15: =IF(H15 = 5, 1, IF(H15 = 4, 0.75, IF(H15 = 3, 0.5, IF(H15 = 2, 0.25, IF(H15 = 1, 0.05, IF(H15 = "<1%", 0.01, IF(H15 = "", ""))))))) | L15: Yes | M15: 1 | N15: =IF(M15 = 5, 1, IF(M15 = 4, 0.75, IF(M15 = 3, 0.5, IF(M15 = 2, 0.25, IF(M15 = 1, 0.05, IF(M15 = "<1%", 0.01, IF(M15 = "", ""))))))) -> 0.05 | O15: 1, 5, Ca, FR | P15: 50 to 500 | Q15: No | S15: =IF(R15 = 5, 1, IF(R15 = 4, 0.75, IF(R15 = 3, 0.5, IF(R15 = 2, 0.25, IF(R15 = 1, 0.05, IF(R15 = "<1%", 0.01, IF(R15 = "", ""))))))) | V15: No | X15: =IF(W15 = 5, 1, IF(W15 = 4, 0.75, IF(W15 = 3, 0.5, IF(W15 = 2, 0.25, IF(W15 = 1, 0.05, IF(W15 = "<1%", 0.01, IF(W15 = "", ""))))))) | AA15: No | AC15: =IF(AB15 = 5, 1, IF(AB15 = 4, 0.75, IF(AB15 = 3, 0.5, IF(AB15 = 2, 0.25, IF(AB15 = 1, 0.05, IF(AB15 = "<1%", 0.01, IF(AB15 = "", "")))))))
A16: 13 | B16: Calla palustris | C16: Marsh callas | D16: Aquatic plant | Plante aquatique | E16: Purple | F16: No | G16: Yes | H16: 1 | I16: =IF(H16 = 5, 1, IF(H16 = 4, 0.75, IF(H16 = 3, 0.5, IF(H16 = 2, 0.25, IF(H16 = 1, 0.05, IF(H16 = "<1%", 0.01, IF(H16 = "", ""))))))) -> 0.05 | J16: 2, 5 | K16: 10 to 50 | L16: No | N16: =IF(M16 = 5, 1, IF(M16 = 4, 0.75, IF(M16 = 3, 0.5, IF(M16 = 2, 0.25, IF(M16 = 1, 0.05, IF(M16 = "<1%", 0.01, IF(M16 = "", ""))))))) | Q16: Yes | R16: 1 | S16: =IF(R16 = 5, 1, IF(R16 = 4, 0.75, IF(R16 = 3, 0.5, IF(R16 = 2, 0.25, IF(R16 = 1, 0.05, IF(R16 = "<1%", 0.01, IF(R16 = "", ""))))))) -> 0.05 | T16: 2, 5 | U16: 0 to 10 | V16: No | X16: =IF(W16 = 5, 1, IF(W16 = 4, 0.75, IF(W16 = 3, 0.5, IF(W16 = 2, 0.25, IF(W16 = 1, 0.05, IF(W16 = "<1%", 0.01, IF(W16 = "", ""))))))) | AA16: No | AC16: =IF(AB16 = 5, 1, IF(AB16 = 4, 0.75, IF(AB16 = 3, 0.5, IF(AB16 = 2, 0.25, IF(AB16 = 1, 0.05, IF(AB16 = "<1%", 0.01, IF(AB16 = "", "")))))))
A17: 14 | B17: Chamaedaphne calyculata | C17: Leatherleaf | D17: Shrub | Arbuste | E17: Purple | F17: Yes | G17: Yes | H17: 1 | I17: =IF(H17 = 5, 1, IF(H17 = 4, 0.75, IF(H17 = 3, 0.5, IF(H17 = 2, 0.25, IF(H17 = 1, 0.05, IF(H17 = "<1%", 0.01, IF(H17 = "", ""))))))) -> 0.05 | J17: 2, 5 | K17: 10 to 50 | L17: Yes | M17: 2 | N17: =IF(M17 = 5, 1, IF(M17 = 4, 0.75, IF(M17 = 3, 0.5, IF(M17 = 2, 0.25, IF(M17 = 1, 0.05, IF(M17 = "<1%", 0.01, IF(M17 = "", ""))))))) -> 0.25 | O17: 2, 2 | P17: 10 to 50 | Q17: Yes | R17: 1 | S17: =IF(R17 = 5, 1, IF(R17 = 4, 0.75, IF(R17 = 3, 0.5, IF(R17 = 2, 0.25, IF(R17 = 1, 0.05, IF(R17 = "<1%", 0.01, IF(R17 = "", ""))))))) -> 0.05 | T17: 2, 2 | U17: 10 to 50 | V17: Yes | W17: 2 | X17: =IF(W17 = 5, 1, IF(W17 = 4, 0.75, IF(W17 = 3, 0.5, IF(W17 = 2, 0.25, IF(W17 = 1, 0.05, IF(W17 = "<1%", 0.01, IF(W17 = "", ""))))))) -> 0.25 | Y17: 2, 2 | Z17: 10 to 50 | AA17: Yes | AB17: 1 | AC17: =IF(AB17 = 5, 1, IF(AB17 = 4, 0.75, IF(AB17 = 3, 0.5, IF(AB17 = 2, 0.25, IF(AB17 = 1, 0.05, IF(AB17 = "<1%", 0.01, IF(AB17 = "", ""))))))) -> 0.05 | AD17: 2, 2 | AE17: 10 to 50
A18: 15 | B18: Dulichium arundinaceum | C18: Three-way sedge | D18: Grass or Sedge | Graminée | E18: Purple | F18: Yes | G18: No | I18: =IF(H18 = 5, 1, IF(H18 = 4, 0.75, IF(H18 = 3, 0.5, IF(H18 = 2, 0.25, IF(H18 = 1, 0.05, IF(H18 = "<1%", 0.01, IF(H18 = "", ""))))))) | L18: No | N18: =IF(M18 = 5, 1, IF(M18 = 4, 0.75, IF(M18 = 3, 0.5, IF(M18 = 2, 0.25, IF(M18 = 1, 0.05, IF(M18 = "<1%", 0.01, IF(M18 = "", ""))))))) | Q18: Yes | R18: 1 | S18: =IF(R18 = 5, 1, IF(R18 = 4, 0.75, IF(R18 = 3, 0.5, IF(R18 = 2, 0.25, IF(R18 = 1, 0.05, IF(R18 = "<1%", 0.01, IF(R18 = "", ""))))))) -> 0.05 | T18: 2, 2 | U18: 10 to 50 | V18: No | X18: =IF(W18 = 5, 1, IF(W18 = 4, 0.75, IF(W18 = 3, 0.5, IF(W18 = 2, 0.25, IF(W18 = 1, 0.05, IF(W18 = "<1%", 0.01, IF(W18 = "", ""))))))) | AA18: No | AC18: =IF(AB18 = 5, 1, IF(AB18 = 4, 0.75, IF(AB18 = 3, 0.5, IF(AB18 = 2, 0.25, IF(AB18 = 1, 0.05, IF(AB18 = "<1%", 0.01, IF(AB18 = "", "")))))))
A19: 16 | B19: Equisetum palustre | C19: Marsh horsetail | D19: Grass or Sedge | Graminée | E19: Purple | F19: No | G19: No | I19: =IF(H19 = 5, 1, IF(H19 = 4, 0.75, IF(H19 = 3, 0.5, IF(H19 = 2, 0.25, IF(H19 = 1, 0.05, IF(H19 = "<1%", 0.01, IF(H19 = "", ""))))))) | L19: Yes | M19: 1 | N19: =IF(M19 = 5, 1, IF(M19 = 4, 0.75, IF(M19 = 3, 0.5, IF(M19 = 2, 0.25, IF(M19 = 1, 0.05, IF(M19 = "<1%", 0.01, IF(M19 = "", ""))))))) -> 0.05 | O19: 1, 2 | P19: 10 to 50 | Q19: No | S19: =IF(R19 = 5, 1, IF(R19 = 4, 0.75, IF(R19 = 3, 0.5, IF(R19 = 2, 0.25, IF(R19 = 1, 0.05, IF(R19 = "<1%", 0.01, IF(R19 = "", ""))))))) | V19: No | X19: =IF(W19 = 5, 1, IF(W19 = 4, 0.75, IF(W19 = 3, 0.5, IF(W19 = 2, 0.25, IF(W19 = 1, 0.05, IF(W19 = "<1%", 0.01, IF(W19 = "", ""))))))) | AA19: No | AC19: =IF(AB19 = 5, 1, IF(AB19 = 4, 0.75, IF(AB19 = 3, 0.5, IF(AB19 = 2, 0.25, IF(AB19 = 1, 0.05, IF(AB19 = "<1%", 0.01, IF(AB19 = "", "")))))))
A20: 17 | B20: Lysimachia sp. | C20: Loosestrifes | D20: Grass or Sedge | Graminée | E20: Purple | F20: No | G20: Yes | H20: 1 | I20: =IF(H20 = 5, 1, IF(H20 = 4, 0.75, IF(H20 = 3, 0.5, IF(H20 = 2, 0.25, IF(H20 = 1, 0.05, IF(H20 = "<1%", 0.01, IF(H20 = "", ""))))))) -> 0.05 | J20: 1, 5 | K20: 0 to 10 | L20: No | N20: =IF(M20 = 5, 1, IF(M20 = 4, 0.75, IF(M20 = 3, 0.5, IF(M20 = 2, 0.25, IF(M20 = 1, 0.05, IF(M20 = "<1%", 0.01, IF(M20 = "", ""))))))) | Q20: No | S20: =IF(R20 = 5, 1, IF(R20 = 4, 0.75, IF(R20 = 3, 0.5, IF(R20 = 2, 0.25, IF(R20 = 1, 0.05, IF(R20 = "<1%", 0.01, IF(R20 = "", ""))))))) | V20: No | X20: =IF(W20 = 5, 1, IF(W20 = 4, 0.75, IF(W20 = 3, 0.5, IF(W20 = 2, 0.25, IF(W20 = 1, 0.05, IF(W20 = "<1%", 0.01, IF(W20 = "", ""))))))) | AA20: No | AC20: =IF(AB20 = 5, 1, IF(AB20 = 4, 0.75, IF(AB20 = 3, 0.5, IF(AB20 = 2, 0.25, IF(AB20 = 1, 0.05, IF(AB20 = "<1%", 0.01, IF(AB20 = "", "")))))))
A21: 18 | B21: Sphagnum sp. | C21: Sphagnum moss | D21: Moss | Mousse | E21: Purple | F21: Yes | G21: Yes | H21: 5 | I21: =IF(H21 = 5, 1, IF(H21 = 4, 0.75, IF(H21 = 3, 0.5, IF(H21 = 2, 0.25, IF(H21 = 1, 0.05, IF(H21 = "<1%", 0.01, IF(H21 = "", ""))))))) -> 1 | J21: 5, 5, DY | K21: 10 to 50 | L21: Yes | M21: 5 | N21: =IF(M21 = 5, 1, IF(M21 = 4, 0.75, IF(M21 = 3, 0.5, IF(M21 = 2, 0.25, IF(M21 = 1, 0.05, IF(M21 = "<1%", 0.01, IF(M21 = "", ""))))))) -> 1 | O21: 5, 5, DY | P21: 10 to 50 | Q21: Yes | R21: 4 | S21: =IF(R21 = 5, 1, IF(R21 = 4, 0.75, IF(R21 = 3, 0.5, IF(R21 = 2, 0.25, IF(R21 = 1, 0.05, IF(R21 = "<1%", 0.01, IF(R21 = "", ""))))))) -> 0.75 | T21: 5, 5 | U21: 10 to 50 | V21: Yes | W21: 5 | X21: =IF(W21 = 5, 1, IF(W21 = 4, 0.75, IF(W21 = 3, 0.5, IF(W21 = 2, 0.25, IF(W21 = 1, 0.05, IF(W21 = "<1%", 0.01, IF(W21 = "", ""))))))) -> 1 | Y21: 5, 5 | Z21: 10 to 50 | AA21: Yes | AB21: 5 | AC21: =IF(AB21 = 5, 1, IF(AB21 = 4, 0.75, IF(AB21 = 3, 0.5, IF(AB21 = 2, 0.25, IF(AB21 = 1, 0.05, IF(AB21 = "<1%", 0.01, IF(AB21 = "", ""))))))) -> 1 | AD21: 5, 5 | AE21: 10 to 50
A22: 19 | B22: Spiraea sp. | C22: Meadowsweets | D22: Shrub | Arbuste | E22: Purple | F22: Yes | G22: Yes | H22: 1 | I22: =IF(H22 = 5, 1, IF(H22 = 4, 0.75, IF(H22 = 3, 0.5, IF(H22 = 2, 0.25, IF(H22 = 1, 0.05, IF(H22 = "<1%", 0.01, IF(H22 = "", ""))))))) -> 0.05 | J22: 1, 5 | K22: 10 to 50 | L22: Yes | M22: 1 | N22: =IF(M22 = 5, 1, IF(M22 = 4, 0.75, IF(M22 = 3, 0.5, IF(M22 = 2, 0.25, IF(M22 = 1, 0.05, IF(M22 = "<1%", 0.01, IF(M22 = "", ""))))))) -> 0.05 | O22: 1, 5 | P22: 10 to 50 | Q22: No | S22: =IF(R22 = 5, 1, IF(R22 = 4, 0.75, IF(R22 = 3, 0.5, IF(R22 = 2, 0.25, IF(R22 = 1, 0.05, IF(R22 = "<1%", 0.01, IF(R22 = "", ""))))))) | V22: Yes | W22: 1 | X22: =IF(W22 = 5, 1, IF(W22 = 4, 0.75, IF(W22 = 3, 0.5, IF(W22 = 2, 0.25, IF(W22 = 1, 0.05, IF(W22 = "<1%", 0.01, IF(W22 = "", ""))))))) -> 0.05 | Y22: 1, 5 | Z22: 10 to 50 | AA22: Yes | AB22: 1 | AC22: =IF(AB22 = 5, 1, IF(AB22 = 4, 0.75, IF(AB22 = 3, 0.5, IF(AB22 = 2, 0.25, IF(AB22 = 1, 0.05, IF(AB22 = "<1%", 0.01, IF(AB22 = "", ""))))))) -> 0.05 | AD22: 1, 5 | AE22: 10 to 50
A23: 20 | B23: Subfamily Cyperoideae | C23: Grass/sedge | D23: Grass or Sedge | Graminée | E23: Purple | F23: No | G23: No | I23: =IF(H23 = 5, 1, IF(H23 = 4, 0.75, IF(H23 = 3, 0.5, IF(H23 = 2, 0.25, IF(H23 = 1, 0.05, IF(H23 = "<1%", 0.01, IF(H23 = "", ""))))))) | L23: Yes | M23: 1 | N23: =IF(M23 = 5, 1, IF(M23 = 4, 0.75, IF(M23 = 3, 0.5, IF(M23 = 2, 0.25, IF(M23 = 1, 0.05, IF(M23 = "<1%", 0.01, IF(M23 = "", ""))))))) -> 0.05 | O23: 2, 7 | P23: 10 to 50 | Q23: Yes | R23: 1 | S23: =IF(R23 = 5, 1, IF(R23 = 4, 0.75, IF(R23 = 3, 0.5, IF(R23 = 2, 0.25, IF(R23 = 1, 0.05, IF(R23 = "<1%", 0.01, IF(R23 = "", ""))))))) -> 0.05 | T23: 2, 7 | U23: 10 to 50 | V23: Yes | W23: 2 | X23: =IF(W23 = 5, 1, IF(W23 = 4, 0.75, IF(W23 = 3, 0.5, IF(W23 = 2, 0.25, IF(W23 = 1, 0.05, IF(W23 = "<1%", 0.01, IF(W23 = "", ""))))))) -> 0.25 | Y23: 2, 7 | Z23: 10 to 50 | AA23: No | AC23: =IF(AB23 = 5, 1, IF(AB23 = 4, 0.75, IF(AB23 = 3, 0.5, IF(AB23 = 2, 0.25, IF(AB23 = 1, 0.05, IF(AB23 = "<1%", 0.01, IF(AB23 = "", "")))))))
A24: 21 | B24: Typha sp. | C24: Cattails | D24: Aquatic plant | Plante aquatique | E24: Purple | F24: Yes | G24: Yes | H24: 1 | I24: =IF(H24 = 5, 1, IF(H24 = 4, 0.75, IF(H24 = 3, 0.5, IF(H24 = 2, 0.25, IF(H24 = 1, 0.05, IF(H24 = "<1%", 0.01, IF(H24 = "", ""))))))) -> 0.05 | J24: 3, 5, Ca | K24: 50 to 200 | L24: Yes | M24: 1 | N24: =IF(M24 = 5, 1, IF(M24 = 4, 0.75, IF(M24 = 3, 0.5, IF(M24 = 2, 0.25, IF(M24 = 1, 0.05, IF(M24 = "<1%", 0.01, IF(M24 = "", ""))))))) -> 0.05 | O24: 3, 5, Ca | P24: 50 to 200 | Q24: Yes | R24: 1 | S24: =IF(R24 = 5, 1, IF(R24 = 4, 0.75, IF(R24 = 3, 0.5, IF(R24 = 2, 0.25, IF(R24 = 1, 0.05, IF(R24 = "<1%", 0.01, IF(R24 = "", ""))))))) -> 0.05 | T24: 3, 5, Ca | U24: 50 to 200 | V24: Yes | W24: 1 | X24: =IF(W24 = 5, 1, IF(W24 = 4, 0.75, IF(W24 = 3, 0.5, IF(W24 = 2, 0.25, IF(W24 = 1, 0.05, IF(W24 = "<1%", 0.01, IF(W24 = "", ""))))))) -> 0.05 | Y24: 3, 5, Ca | Z24: 50 to 200 | AA24: Yes | AB24: 1 | AC24: =IF(AB24 = 5, 1, IF(AB24 = 4, 0.75, IF(AB24 = 3, 0.5, IF(AB24 = 2, 0.25, IF(AB24 = 1, 0.05, IF(AB24 = "<1%", 0.01, IF(AB24 = "", ""))))))) -> 0.05 | AD24: 1, 5, Ca | AE24: 50 to 200
A25: 22 | B25: Chamaedaphne calyculata | C25: Leatherleaf | D25: Evergreen tree | Arbre sempervirent | E25: Yellow | F25: Yes | G25: Yes | H25: 5 | I25: =IF(H25 = 5, 1, IF(H25 = 4, 0.75, IF(H25 = 3, 0.5, IF(H25 = 2, 0.25, IF(H25 = 1, 0.05, IF(H25 = "<1%", 0.01, IF(H25 = "", ""))))))) -> 1 | J25: 5 | L25: Yes | M25: 4 | N25: =IF(M25 = 5, 1, IF(M25 = 4, 0.75, IF(M25 = 3, 0.5, IF(M25 = 2, 0.25, IF(M25 = 1, 0.05, IF(M25 = "<1%", 0.01, IF(M25 = "", ""))))))) -> 0.75 | Q25: Yes | R25: 4 | S25: =IF(R25 = 5, 1, IF(R25 = 4, 0.75, IF(R25 = 3, 0.5, IF(R25 = 2, 0.25, IF(R25 = 1, 0.05, IF(R25 = "<1%", 0.01, IF(R25 = "", ""))))))) -> 0.75 | V25: No | X25: =IF(W25 = 5, 1, IF(W25 = 4, 0.75, IF(W25 = 3, 0.5, IF(W25 = 2, 0.25, IF(W25 = 1, 0.05, IF(W25 = "<1%", 0.01, IF(W25 = "", ""))))))) | AA25: Yes | AB25: 3 | AC25: =IF(AB25 = 5, 1, IF(AB25 = 4, 0.75, IF(AB25 = 3, 0.5, IF(AB25 = 2, 0.25, IF(AB25 = 1, 0.05, IF(AB25 = "<1%", 0.01, IF(AB25 = "", ""))))))) -> 0.5
A26: 23 | B26: Larix laricina | C26: Larch | D26: Deciduous tree | Arbre décidu | E26: Yellow | F26: No | G26: Yes | H26: 1 | I26: =IF(H26 = 5, 1, IF(H26 = 4, 0.75, IF(H26 = 3, 0.5, IF(H26 = 2, 0.25, IF(H26 = 1, 0.05, IF(H26 = "<1%", 0.01, IF(H26 = "", ""))))))) -> 0.05 | J26: SP | K26: 64 | L26: No | N26: =IF(M26 = 5, 1, IF(M26 = 4, 0.75, IF(M26 = 3, 0.5, IF(M26 = 2, 0.25, IF(M26 = 1, 0.05, IF(M26 = "<1%", 0.01, IF(M26 = "", ""))))))) | Q26: Yes | S26: =IF(R26 = 5, 1, IF(R26 = 4, 0.75, IF(R26 = 3, 0.5, IF(R26 = 2, 0.25, IF(R26 = 1, 0.05, IF(R26 = "<1%", 0.01, IF(R26 = "", ""))))))) | V26: Yes | W26: 1 | X26: =IF(W26 = 5, 1, IF(W26 = 4, 0.75, IF(W26 = 3, 0.5, IF(W26 = 2, 0.25, IF(W26 = 1, 0.05, IF(W26 = "<1%", 0.01, IF(W26 = "", ""))))))) -> 0.05 | Y26: 1 DD, 1 SP | AA26: Yes | AB26: 1 | AC26: =IF(AB26 = 5, 1, IF(AB26 = 4, 0.75, IF(AB26 = 3, 0.5, IF(AB26 = 2, 0.25, IF(AB26 = 1, 0.05, IF(AB26 = "<1%", 0.01, IF(AB26 = "", ""))))))) -> 0.05 | AD26: FR, SP
A27: 24 | B27: Aronia melanocarpa | C27: Black chockeberry | D27: Shrub | Arbuste | E27: Yellow | F27: No | G27: No | I27: =IF(H27 = 5, 1, IF(H27 = 4, 0.75, IF(H27 = 3, 0.5, IF(H27 = 2, 0.25, IF(H27 = 1, 0.05, IF(H27 = "<1%", 0.01, IF(H27 = "", ""))))))) | L27: No | N27: =IF(M27 = 5, 1, IF(M27 = 4, 0.75, IF(M27 = 3, 0.5, IF(M27 = 2, 0.25, IF(M27 = 1, 0.05, IF(M27 = "<1%", 0.01, IF(M27 = "", ""))))))) | Q27: No | S27: =IF(R27 = 5, 1, IF(R27 = 4, 0.75, IF(R27 = 3, 0.5, IF(R27 = 2, 0.25, IF(R27 = 1, 0.05, IF(R27 = "<1%", 0.01, IF(R27 = "", ""))))))) | V27: Yes | W27: 0 | X27: 0.01 | Y27: Small dense clumps | Z27: 10 to 50 | AA27: Yes | AB27: 1 | AC27: =IF(AB27 = 5, 1, IF(AB27 = 4, 0.75, IF(AB27 = 3, 0.5, IF(AB27 = 2, 0.25, IF(AB27 = 1, 0.05, IF(AB27 = "<1%", 0.01, IF(AB27 = "", ""))))))) -> 0.05
A28: 25 | B28: Eriophorum angostifolium | C28: Cotton Grass | D28: Grass or Sedge | Graminée | E28: Yellow | F28: No | G28: No | I28: =IF(H28 = 5, 1, IF(H28 = 4, 0.75, IF(H28 = 3, 0.5, IF(H28 = 2, 0.25, IF(H28 = 1, 0.05, IF(H28 = "<1%", 0.01, IF(H28 = "", ""))))))) | L28: No | N28: =IF(M28 = 5, 1, IF(M28 = 4, 0.75, IF(M28 = 3, 0.5, IF(M28 = 2, 0.25, IF(M28 = 1, 0.05, IF(M28 = "<1%", 0.01, IF(M28 = "", ""))))))) | Q28: Yes | R28: 1 | S28: =IF(R28 = 5, 1, IF(R28 = 4, 0.75, IF(R28 = 3, 0.5, IF(R28 = 2, 0.25, IF(R28 = 1, 0.05, IF(R28 = "<1%", 0.01, IF(R28 = "", ""))))))) -> 0.05 | V28: Yes | W28: 5 | X28: =IF(W28 = 5, 1, IF(W28 = 4, 0.75, IF(W28 = 3, 0.5, IF(W28 = 2, 0.25, IF(W28 = 1, 0.05, IF(W28 = "<1%", 0.01, IF(W28 = "", ""))))))) -> 1 | AA28: Yes | AB28: 1 | AC28: =IF(AB28 = 5, 1, IF(AB28 = 4, 0.75, IF(AB28 = 3, 0.5, IF(AB28 = 2, 0.25, IF(AB28 = 1, 0.05, IF(AB28 = "<1%", 0.01, IF(AB28 = "", ""))))))) -> 0.05 | AD28: B
A29: 26 | B29: Rhododendron neoglandulosum | C29: Labrador Tea | D29: Shrub | Arbuste | E29: Yellow | F29: No | G29: Yes | H29: 4 | I29: =IF(H29 = 5, 1, IF(H29 = 4, 0.75, IF(H29 = 3, 0.5, IF(H29 = 2, 0.25, IF(H29 = 1, 0.05, IF(H29 = "<1%", 0.01, IF(H29 = "", ""))))))) -> 0.75 | J29: GE | K29: 10 to 50 | L29: Yes | M29: 3 | N29: =IF(M29 = 5, 1, IF(M29 = 4, 0.75, IF(M29 = 3, 0.5, IF(M29 = 2, 0.25, IF(M29 = 1, 0.05, IF(M29 = "<1%", 0.01, IF(M29 = "", ""))))))) -> 0.5 | Q29: Yes | R29: 4 | S29: =IF(R29 = 5, 1, IF(R29 = 4, 0.75, IF(R29 = 3, 0.5, IF(R29 = 2, 0.25, IF(R29 = 1, 0.05, IF(R29 = "<1%", 0.01, IF(R29 = "", ""))))))) -> 0.75 | V29: Yes | W29: 4 | X29: =IF(W29 = 5, 1, IF(W29 = 4, 0.75, IF(W29 = 3, 0.5, IF(W29 = 2, 0.25, IF(W29 = 1, 0.05, IF(W29 = "<1%", 0.01, IF(W29 = "", ""))))))) -> 0.75 | AA29: Yes | AB29: 3 | AC29: =IF(AB29 = 5, 1, IF(AB29 = 4, 0.75, IF(AB29 = 3, 0.5, IF(AB29 = 2, 0.25, IF(AB29 = 1, 0.05, IF(AB29 = "<1%", 0.01, IF(AB29 = "", ""))))))) -> 0.5
A30: 27 | B30: Sphagnum | C30: Common peat moss | D30: Moss | Mousse | E30: Yellow | F30: Yes | G30: Yes | H30: 5 | I30: =IF(H30 = 5, 1, IF(H30 = 4, 0.75, IF(H30 = 3, 0.5, IF(H30 = 2, 0.25, IF(H30 = 1, 0.05, IF(H30 = "<1%", 0.01, IF(H30 = "", ""))))))) -> 1 | L30: Yes | M30: 5 | N30: =IF(M30 = 5, 1, IF(M30 = 4, 0.75, IF(M30 = 3, 0.5, IF(M30 = 2, 0.25, IF(M30 = 1, 0.05, IF(M30 = "<1%", 0.01, IF(M30 = "", ""))))))) -> 1 | Q30: yes | R30: 5 | S30: =IF(R30 = 5, 1, IF(R30 = 4, 0.75, IF(R30 = 3, 0.5, IF(R30 = 2, 0.25, IF(R30 = 1, 0.05, IF(R30 = "<1%", 0.01, IF(R30 = "", ""))))))) -> 1 | V30: Yes | W30: 5 | X30: =IF(W30 = 5, 1, IF(W30 = 4, 0.75, IF(W30 = 3, 0.5, IF(W30 = 2, 0.25, IF(W30 = 1, 0.05, IF(W30 = "<1%", 0.01, IF(W30 = "", ""))))))) -> 1 | AA30: Yes | AB30: 5 | AC30: =IF(AB30 = 5, 1, IF(AB30 = 4, 0.75, IF(AB30 = 3, 0.5, IF(AB30 = 2, 0.25, IF(AB30 = 1, 0.05, IF(AB30 = "<1%", 0.01, IF(AB30 = "", ""))))))) -> 1
A31: 28 | B31: Vaccinium Cyanococcus | C31: Blueberry | D31: Shrub | Arbuste | E31: Yellow | F31: No | G31: Yes | H31: 4 | I31: =IF(H31 = 5, 1, IF(H31 = 4, 0.75, IF(H31 = 3, 0.5, IF(H31 = 2, 0.25, IF(H31 = 1, 0.05, IF(H31 = "<1%", 0.01, IF(H31 = "", ""))))))) -> 0.75 | L31: Yes | M31: 3 | N31: =IF(M31 = 5, 1, IF(M31 = 4, 0.75, IF(M31 = 3, 0.5, IF(M31 = 2, 0.25, IF(M31 = 1, 0.05, IF(M31 = "<1%", 0.01, IF(M31 = "", ""))))))) -> 0.5 | Q31: Yes | R31: 4 | S31: =IF(R31 = 5, 1, IF(R31 = 4, 0.75, IF(R31 = 3, 0.5, IF(R31 = 2, 0.25, IF(R31 = 1, 0.05, IF(R31 = "<1%", 0.01, IF(R31 = "", ""))))))) -> 0.75 | V31: No | X31: =IF(W31 = 5, 1, IF(W31 = 4, 0.75, IF(W31 = 3, 0.5, IF(W31 = 2, 0.25, IF(W31 = 1, 0.05, IF(W31 = "<1%", 0.01, IF(W31 = "", ""))))))) | AA31: No | AC31: =IF(AB31 = 5, 1, IF(AB31 = 4, 0.75, IF(AB31 = 3, 0.5, IF(AB31 = 2, 0.25, IF(AB31 = 1, 0.05, IF(AB31 = "<1%", 0.01, IF(AB31 = "", "")))))))

Sheet BioBlitz Surveys - Forest
B1: Identification Information | Informations d'identification | F1: Prevalence Across Sites | Prévalence parmi les sites | G1: Plot 1 | L1: Plot 2 | Q1: Plot 3 | V1: Plot 4 | AA1: Plot 5
A2: Obs. no. | B2: Latin name | Nom latin | C2: Common name | Nom commun | D2: Taxon type | Type de taxon [Dropdown menu] | E2: Group Colour | Couleur de groupe | F2: Do you see this organism yet on the list? | Est-ce que vous voyez déjà cet organisme sur la liste? (Yes or No) | G2: Plot 1 Presence | H2: Plot 1 Cover | I2: DO NOT CHANGE Cover proportion | J2: Other remarks | K2: Height (cm) | L2: Plot 2 Presence | M2: Plot 2 Cover | N2: DO NOT CHANGE Cover proportion | O2: Other remarks | P2: Height (cm) | Q2: Plot 3 Presence | R2: Plot 3 Cover | S2: DO NOT CHANGE Cover proportion | T2: Other remarks | U2: Height (cm) | V2: Plot 4 Presence | W2: Plot 4 Cover | X2: DO NOT CHANGE Cover proportion | Y2: Other remarks | Z2: Height (cm) | AA2: Plot 5 Presence | AB2: Plot 5 Cover | AC2: DO NOT CHANGE Cover proportion | AD2: Other remarks | AE2: Height (cm)
A3: EXAMPLE | B3: Larix laricina | C3: Tamarack | D3: Evergreen tree | Arbre sempervirent | E3: Purple | F3: Yes | G3: Yes | H3: 4 | I3: =IF(H3 = 5, 1, IF(H3 = 4, 0.75, IF(H3 = 3, 0.5, IF(H3 = 2, 0.25, IF(H3 = 1, 0.05, IF(H3 = "<1%", 0.01, IF(H3 = "", ""))))))) -> 0.75 | J3: 1 | K3: 6 | L3: Yes | M3: 3 | N3: =IF(M3 = 5, 1, IF(M3 = 4, 0.75, IF(M3 = 3, 0.5, IF(M3 = 2, 0.25, IF(M3 = 1, 0.05, IF(M3 = "<1%", 0.01, IF(M3 = "", ""))))))) -> 0.5 | O3: 1 | P3: 6 | Q3: No | S3: =IF(R3 = 5, 1, IF(R3 = 4, 0.75, IF(R3 = 3, 0.5, IF(R3 = 2, 0.25, IF(R3 = 1, 0.05, IF(R3 = "<1%", 0.01, IF(R3 = "", ""))))))) | V3: No | X3: =IF(W3 = 5, 1, IF(W3 = 4, 0.75, IF(W3 = 3, 0.5, IF(W3 = 2, 0.25, IF(W3 = 1, 0.05, IF(W3 = "<1%", 0.01, IF(W3 = "", ""))))))) | AA3: Yes | AB3: 5 | AC3: =IF(AB3 = 5, 1, IF(AB3 = 4, 0.75, IF(AB3 = 3, 0.5, IF(AB3 = 2, 0.25, IF(AB3 = 1, 0.05, IF(AB3 = "<1%", 0.01, IF(AB3 = "", ""))))))) -> 1 | AD3: 1 | AE3: 6
A4: 1 | B4: Acer | C4: Maple | D4: Deciduous tree | Arbre décidu | E4: Pink | F4: Yes | G4: no | I4: =IF(H4 = 5, 1, IF(H4 = 4, 0.75, IF(H4 = 3, 0.5, IF(H4 = 2, 0.25, IF(H4 = 1, 0.05, IF(H4 = "<1%", 0.01, IF(H4 = "", ""))))))) | L4: no | N4: =IF(M4 = 5, 1, IF(M4 = 4, 0.75, IF(M4 = 3, 0.5, IF(M4 = 2, 0.25, IF(M4 = 1, 0.05, IF(M4 = "<1%", 0.01, IF(M4 = "", ""))))))) | Q4: no | S4: =IF(R4 = 5, 1, IF(R4 = 4, 0.75, IF(R4 = 3, 0.5, IF(R4 = 2, 0.25, IF(R4 = 1, 0.05, IF(R4 = "<1%", 0.01, IF(R4 = "", ""))))))) | X4: =IF(W4 = 5, 1, IF(W4 = 4, 0.75, IF(W4 = 3, 0.5, IF(W4 = 2, 0.25, IF(W4 = 1, 0.05, IF(W4 = "<1%", 0.01, IF(W4 = "", ""))))))) | AA4: yes | AB4: 1 | AC4: =IF(AB4 = 5, 1, IF(AB4 = 4, 0.75, IF(AB4 = 3, 0.5, IF(AB4 = 2, 0.25, IF(AB4 = 1, 0.05, IF(AB4 = "<1%", 0.01, IF(AB4 = "", ""))))))) -> 0.05 | AD4: BHD 5.5cm | AE4: 400
A5: 2 | B5: Anthyrium angustum | C5: Northern Lady fern | D5: Fern | Fougère | E5: Pink | F5: No | G5: no | I5: =IF(H5 = 5, 1, IF(H5 = 4, 0.75, IF(H5 = 3, 0.5, IF(H5 = 2, 0.25, IF(H5 = 1, 0.05, IF(H5 = "<1%", 0.01, IF(H5 = "", ""))))))) | L5: no | N5: =IF(M5 = 5, 1, IF(M5 = 4, 0.75, IF(M5 = 3, 0.5, IF(M5 = 2, 0.25, IF(M5 = 1, 0.05, IF(M5 = "<1%", 0.01, IF(M5 = "", ""))))))) | Q5: yes | R5: 2 | S5: =IF(R5 = 5, 1, IF(R5 = 4, 0.75, IF(R5 = 3, 0.5, IF(R5 = 2, 0.25, IF(R5 = 1, 0.05, IF(R5 = "<1%", 0.01, IF(R5 = "", ""))))))) -> 0.25 | U5: 2 | X5: =IF(W5 = 5, 1, IF(W5 = 4, 0.75, IF(W5 = 3, 0.5, IF(W5 = 2, 0.25, IF(W5 = 1, 0.05, IF(W5 = "<1%", 0.01, IF(W5 = "", ""))))))) | AA5: no | AC5: =IF(AB5 = 5, 1, IF(AB5 = 4, 0.75, IF(AB5 = 3, 0.5, IF(AB5 = 2, 0.25, IF(AB5 = 1, 0.05, IF(AB5 = "<1%", 0.01, IF(AB5 = "", "")))))))
A6: 3 | B6: Asclepias incarnata | C6: Swamp milkweed | D6: Grass or Sedge | Graminée | E6: Pink | F6: No | G6: no | I6: =IF(H6 = 5, 1, IF(H6 = 4, 0.75, IF(H6 = 3, 0.5, IF(H6 = 2, 0.25, IF(H6 = 1, 0.05, IF(H6 = "<1%", 0.01, IF(H6 = "", ""))))))) | L6: no | N6: =IF(M6 = 5, 1, IF(M6 = 4, 0.75, IF(M6 = 3, 0.5, IF(M6 = 2, 0.25, IF(M6 = 1, 0.05, IF(M6 = "<1%", 0.01, IF(M6 = "", ""))))))) | Q6: yes | R6: 1 | S6: =IF(R6 = 5, 1, IF(R6 = 4, 0.75, IF(R6 = 3, 0.5, IF(R6 = 2, 0.25, IF(R6 = 1, 0.05, IF(R6 = "<1%", 0.01, IF(R6 = "", ""))))))) -> 0.05 | U6: 1 | X6: =IF(W6 = 5, 1, IF(W6 = 4, 0.75, IF(W6 = 3, 0.5, IF(W6 = 2, 0.25, IF(W6 = 1, 0.05, IF(W6 = "<1%", 0.01, IF(W6 = "", ""))))))) | AA6: no | AC6: =IF(AB6 = 5, 1, IF(AB6 = 4, 0.75, IF(AB6 = 3, 0.5, IF(AB6 = 2, 0.25, IF(AB6 = 1, 0.05, IF(AB6 = "<1%", 0.01, IF(AB6 = "", "")))))))
A7: 4 | B7: Chinavia hilaris | C7: Green stink bug | D7: Insect | Insecte | E7: Pink | F7: No | G7: no | I7: =IF(H7 = 5, 1, IF(H7 = 4, 0.75, IF(H7 = 3, 0.5, IF(H7 = 2, 0.25, IF(H7 = 1, 0.05, IF(H7 = "<1%", 0.01, IF(H7 = "", ""))))))) | L7: no | N7: =IF(M7 = 5, 1, IF(M7 = 4, 0.75, IF(M7 = 3, 0.5, IF(M7 = 2, 0.25, IF(M7 = 1, 0.05, IF(M7 = "<1%", 0.01, IF(M7 = "", ""))))))) | Q7: no | S7: =IF(R7 = 5, 1, IF(R7 = 4, 0.75, IF(R7 = 3, 0.5, IF(R7 = 2, 0.25, IF(R7 = 1, 0.05, IF(R7 = "<1%", 0.01, IF(R7 = "", ""))))))) | X7: =IF(W7 = 5, 1, IF(W7 = 4, 0.75, IF(W7 = 3, 0.5, IF(W7 = 2, 0.25, IF(W7 = 1, 0.05, IF(W7 = "<1%", 0.01, IF(W7 = "", ""))))))) | AA7: yes | AC7: =IF(AB7 = 5, 1, IF(AB7 = 4, 0.75, IF(AB7 = 3, 0.5, IF(AB7 = 2, 0.25, IF(AB7 = 1, 0.05, IF(AB7 = "<1%", 0.01, IF(AB7 = "", "")))))))
A8: 5 | B8: Doellingeria umbellata | C8: Flat-top White Aster | D8: Grass or Sedge | Graminée | E8: Pink | F8: Yes | G8: no | I8: =IF(H8 = 5, 1, IF(H8 = 4, 0.75, IF(H8 = 3, 0.5, IF(H8 = 2, 0.25, IF(H8 = 1, 0.05, IF(H8 = "<1%", 0.01, IF(H8 = "", ""))))))) | L8: no | N8: =IF(M8 = 5, 1, IF(M8 = 4, 0.75, IF(M8 = 3, 0.5, IF(M8 = 2, 0.25, IF(M8 = 1, 0.05, IF(M8 = "<1%", 0.01, IF(M8 = "", ""))))))) | Q8: no | S8: =IF(R8 = 5, 1, IF(R8 = 4, 0.75, IF(R8 = 3, 0.5, IF(R8 = 2, 0.25, IF(R8 = 1, 0.05, IF(R8 = "<1%", 0.01, IF(R8 = "", ""))))))) | V8: yes | W8: 1 | X8: =IF(W8 = 5, 1, IF(W8 = 4, 0.75, IF(W8 = 3, 0.5, IF(W8 = 2, 0.25, IF(W8 = 1, 0.05, IF(W8 = "<1%", 0.01, IF(W8 = "", ""))))))) -> 0.05 | Z8: 2 | AA8: yes | AB8: 1 | AC8: =IF(AB8 = 5, 1, IF(AB8 = 4, 0.75, IF(AB8 = 3, 0.5, IF(AB8 = 2, 0.25, IF(AB8 = 1, 0.05, IF(AB8 = "<1%", 0.01, IF(AB8 = "", ""))))))) -> 0.05 | AE8: 3
A9: 6 | B9: Equisetum pratense | C9: Meadow horsetail | D9: Grass or Sedge | Graminée | E9: Pink | F9: No | G9: yes | H9: 1 | I9: =IF(H9 = 5, 1, IF(H9 = 4, 0.75, IF(H9 = 3, 0.5, IF(H9 = 2, 0.25, IF(H9 = 1, 0.05, IF(H9 = "<1%", 0.01, IF(H9 = "", ""))))))) -> 0.05 | K9: 1 | L9: yes | M9: 1 | N9: =IF(M9 = 5, 1, IF(M9 = 4, 0.75, IF(M9 = 3, 0.5, IF(M9 = 2, 0.25, IF(M9 = 1, 0.05, IF(M9 = "<1%", 0.01, IF(M9 = "", ""))))))) -> 0.05 | P9: 1 | Q9: no | S9: =IF(R9 = 5, 1, IF(R9 = 4, 0.75, IF(R9 = 3, 0.5, IF(R9 = 2, 0.25, IF(R9 = 1, 0.05, IF(R9 = "<1%", 0.01, IF(R9 = "", ""))))))) | X9: =IF(W9 = 5, 1, IF(W9 = 4, 0.75, IF(W9 = 3, 0.5, IF(W9 = 2, 0.25, IF(W9 = 1, 0.05, IF(W9 = "<1%", 0.01, IF(W9 = "", ""))))))) | AA9: no | AC9: =IF(AB9 = 5, 1, IF(AB9 = 4, 0.75, IF(AB9 = 3, 0.5, IF(AB9 = 2, 0.25, IF(AB9 = 1, 0.05, IF(AB9 = "<1%", 0.01, IF(AB9 = "", "")))))))
A10: 7 | B10: Frangula alnus | C10: glossy buckthorn | D10: Deciduous tree | Arbre décidu | E10: Pink | F10: Yes | G10: no | I10: =IF(H10 = 5, 1, IF(H10 = 4, 0.75, IF(H10 = 3, 0.5, IF(H10 = 2, 0.25, IF(H10 = 1, 0.05, IF(H10 = "<1%", 0.01, IF(H10 = "", ""))))))) | L10: yes | M10: 2 | N10: =IF(M10 = 5, 1, IF(M10 = 4, 0.75, IF(M10 = 3, 0.5, IF(M10 = 2, 0.25, IF(M10 = 1, 0.05, IF(M10 = "<1%", 0.01, IF(M10 = "", ""))))))) -> 0.25 | P10: 500 | Q10: no | S10: =IF(R10 = 5, 1, IF(R10 = 4, 0.75, IF(R10 = 3, 0.5, IF(R10 = 2, 0.25, IF(R10 = 1, 0.05, IF(R10 = "<1%", 0.01, IF(R10 = "", ""))))))) | X10: =IF(W10 = 5, 1, IF(W10 = 4, 0.75, IF(W10 = 3, 0.5, IF(W10 = 2, 0.25, IF(W10 = 1, 0.05, IF(W10 = "<1%", 0.01, IF(W10 = "", ""))))))) | AA10: no | AC10: =IF(AB10 = 5, 1, IF(AB10 = 4, 0.75, IF(AB10 = 3, 0.5, IF(AB10 = 2, 0.25, IF(AB10 = 1, 0.05, IF(AB10 = "<1%", 0.01, IF(AB10 = "", "")))))))
A11: 8 | B11: Galium palustre | C11: Common marsh bed straw | D11: Grass or Sedge | Graminée | E11: Pink | F11: No | G11: yes | H11: 1 | I11: =IF(H11 = 5, 1, IF(H11 = 4, 0.75, IF(H11 = 3, 0.5, IF(H11 = 2, 0.25, IF(H11 = 1, 0.05, IF(H11 = "<1%", 0.01, IF(H11 = "", ""))))))) -> 0.05 | K11: 1 | L11: no | N11: =IF(M11 = 5, 1, IF(M11 = 4, 0.75, IF(M11 = 3, 0.5, IF(M11 = 2, 0.25, IF(M11 = 1, 0.05, IF(M11 = "<1%", 0.01, IF(M11 = "", ""))))))) | Q11: no | S11: =IF(R11 = 5, 1, IF(R11 = 4, 0.75, IF(R11 = 3, 0.5, IF(R11 = 2, 0.25, IF(R11 = 1, 0.05, IF(R11 = "<1%", 0.01, IF(R11 = "", ""))))))) | X11: =IF(W11 = 5, 1, IF(W11 = 4, 0.75, IF(W11 = 3, 0.5, IF(W11 = 2, 0.25, IF(W11 = 1, 0.05, IF(W11 = "<1%", 0.01, IF(W11 = "", ""))))))) | AA11: no | AC11: =IF(AB11 = 5, 1, IF(AB11 = 4, 0.75, IF(AB11 = 3, 0.5, IF(AB11 = 2, 0.25, IF(AB11 = 1, 0.05, IF(AB11 = "<1%", 0.01, IF(AB11 = "", "")))))))
A12: 9 | B12: gastropoda | C12: snails | D12: Insect | Insecte | E12: pink | F12: No | G12: no | I12: =IF(H12 = 5, 1, IF(H12 = 4, 0.75, IF(H12 = 3, 0.5, IF(H12 = 2, 0.25, IF(H12 = 1, 0.05, IF(H12 = "<1%", 0.01, IF(H12 = "", ""))))))) | N12: =IF(M12 = 5, 1, IF(M12 = 4, 0.75, IF(M12 = 3, 0.5, IF(M12 = 2, 0.25, IF(M12 = 1, 0.05, IF(M12 = "<1%", 0.01, IF(M12 = "", ""))))))) | S12: =IF(R12 = 5, 1, IF(R12 = 4, 0.75, IF(R12 = 3, 0.5, IF(R12 = 2, 0.25, IF(R12 = 1, 0.05, IF(R12 = "<1%", 0.01, IF(R12 = "", ""))))))) | X12: =IF(W12 = 5, 1, IF(W12 = 4, 0.75, IF(W12 = 3, 0.5, IF(W12 = 2, 0.25, IF(W12 = 1, 0.05, IF(W12 = "<1%", 0.01, IF(W12 = "", ""))))))) | AA12: yes | AB12: 2 | AC12: =IF(AB12 = 5, 1, IF(AB12 = 4, 0.75, IF(AB12 = 3, 0.5, IF(AB12 = 2, 0.25, IF(AB12 = 1, 0.05, IF(AB12 = "<1%", 0.01, IF(AB12 = "", ""))))))) -> 0.25 | AE12: 1
A13: 10 | B13: Geum macrophyllum | C13: Large leafed Avens | D13: Grass or Sedge | Graminée | E13: Pink | F13: No | G13: yes | H13: 1 | I13: =IF(H13 = 5, 1, IF(H13 = 4, 0.75, IF(H13 = 3, 0.5, IF(H13 = 2, 0.25, IF(H13 = 1, 0.05, IF(H13 = "<1%", 0.01, IF(H13 = "", ""))))))) -> 0.05 | K13: 1 | L13: no | N13: =IF(M13 = 5, 1, IF(M13 = 4, 0.75, IF(M13 = 3, 0.5, IF(M13 = 2, 0.25, IF(M13 = 1, 0.05, IF(M13 = "<1%", 0.01, IF(M13 = "", ""))))))) | Q13: no | S13: =IF(R13 = 5, 1, IF(R13 = 4, 0.75, IF(R13 = 3, 0.5, IF(R13 = 2, 0.25, IF(R13 = 1, 0.05, IF(R13 = "<1%", 0.01, IF(R13 = "", ""))))))) | X13: =IF(W13 = 5, 1, IF(W13 = 4, 0.75, IF(W13 = 3, 0.5, IF(W13 = 2, 0.25, IF(W13 = 1, 0.05, IF(W13 = "<1%", 0.01, IF(W13 = "", ""))))))) | AA13: no | AC13: =IF(AB13 = 5, 1, IF(AB13 = 4, 0.75, IF(AB13 = 3, 0.5, IF(AB13 = 2, 0.25, IF(AB13 = 1, 0.05, IF(AB13 = "<1%", 0.01, IF(AB13 = "", "")))))))
A14: 11 | B14: Halyomorpha halys | C14: brown stink bug | D14: Insect | Insecte | E14: Pink | F14: No | G14: no | I14: =IF(H14 = 5, 1, IF(H14 = 4, 0.75, IF(H14 = 3, 0.5, IF(H14 = 2, 0.25, IF(H14 = 1, 0.05, IF(H14 = "<1%", 0.01, IF(H14 = "", ""))))))) | L14: no | N14: =IF(M14 = 5, 1, IF(M14 = 4, 0.75, IF(M14 = 3, 0.5, IF(M14 = 2, 0.25, IF(M14 = 1, 0.05, IF(M14 = "<1%", 0.01, IF(M14 = "", ""))))))) | Q14: no | S14: =IF(R14 = 5, 1, IF(R14 = 4, 0.75, IF(R14 = 3, 0.5, IF(R14 = 2, 0.25, IF(R14 = 1, 0.05, IF(R14 = "<1%", 0.01, IF(R14 = "", ""))))))) | X14: =IF(W14 = 5, 1, IF(W14 = 4, 0.75, IF(W14 = 3, 0.5, IF(W14 = 2, 0.25, IF(W14 = 1, 0.05, IF(W14 = "<1%", 0.01, IF(W14 = "", ""))))))) | AA14: yes | AC14: =IF(AB14 = 5, 1, IF(AB14 = 4, 0.75, IF(AB14 = 3, 0.5, IF(AB14 = 2, 0.25, IF(AB14 = 1, 0.05, IF(AB14 = "<1%", 0.01, IF(AB14 = "", "")))))))
A15: 12 | B15: Hypnales | C15: Feather Moss | D15: Moss | Mousse | E15: Pink | F15: No | G15: yes | H15: 2 | I15: =IF(H15 = 5, 1, IF(H15 = 4, 0.75, IF(H15 = 3, 0.5, IF(H15 = 2, 0.25, IF(H15 = 1, 0.05, IF(H15 = "<1%", 0.01, IF(H15 = "", ""))))))) -> 0.25 | K15: 1 | L15: no | N15: =IF(M15 = 5, 1, IF(M15 = 4, 0.75, IF(M15 = 3, 0.5, IF(M15 = 2, 0.25, IF(M15 = 1, 0.05, IF(M15 = "<1%", 0.01, IF(M15 = "", ""))))))) | Q15: no | S15: =IF(R15 = 5, 1, IF(R15 = 4, 0.75, IF(R15 = 3, 0.5, IF(R15 = 2, 0.25, IF(R15 = 1, 0.05, IF(R15 = "<1%", 0.01, IF(R15 = "", ""))))))) | X15: =IF(W15 = 5, 1, IF(W15 = 4, 0.75, IF(W15 = 3, 0.5, IF(W15 = 2, 0.25, IF(W15 = 1, 0.05, IF(W15 = "<1%", 0.01, IF(W15 = "", ""))))))) | AA15: no | AC15: =IF(AB15 = 5, 1, IF(AB15 = 4, 0.75, IF(AB15 = 3, 0.5, IF(AB15 = 2, 0.25, IF(AB15 = 1, 0.05, IF(AB15 = "<1%", 0.01, IF(AB15 = "", "")))))))
A16: 13 | B16: Impatiens capensis | C16: Jewel weed | D16: Grass or Sedge | Graminée | E16: Pink | F16: No | G16: no | I16: =IF(H16 = 5, 1, IF(H16 = 4, 0.75, IF(H16 = 3, 0.5, IF(H16 = 2, 0.25, IF(H16 = 1, 0.05, IF(H16 = "<1%", 0.01, IF(H16 = "", ""))))))) | L16: yes | M16: 2 | N16: =IF(M16 = 5, 1, IF(M16 = 4, 0.75, IF(M16 = 3, 0.5, IF(M16 = 2, 0.25, IF(M16 = 1, 0.05, IF(M16 = "<1%", 0.01, IF(M16 = "", ""))))))) -> 0.25 | P16: 1 | Q16: no | S16: =IF(R16 = 5, 1, IF(R16 = 4, 0.75, IF(R16 = 3, 0.5, IF(R16 = 2, 0.25, IF(R16 = 1, 0.05, IF(R16 = "<1%", 0.01, IF(R16 = "", ""))))))) | X16: =IF(W16 = 5, 1, IF(W16 = 4, 0.75, IF(W16 = 3, 0.5, IF(W16 = 2, 0.25, IF(W16 = 1, 0.05, IF(W16 = "<1%", 0.01, IF(W16 = "", ""))))))) | AA16: no | AC16: =IF(AB16 = 5, 1, IF(AB16 = 4, 0.75, IF(AB16 = 3, 0.5, IF(AB16 = 2, 0.25, IF(AB16 = 1, 0.05, IF(AB16 = "<1%", 0.01, IF(AB16 = "", "")))))))
A17: 14 | B17: Lythrum Salicaria | C17: Purple Loosestrife | D17: Grass or Sedge | Graminée | E17: Pink | F17: No | G17: yes | H17: 1 | I17: =IF(H17 = 5, 1, IF(H17 = 4, 0.75, IF(H17 = 3, 0.5, IF(H17 = 2, 0.25, IF(H17 = 1, 0.05, IF(H17 = "<1%", 0.01, IF(H17 = "", ""))))))) -> 0.05 | K17: 2 | L17: no | N17: =IF(M17 = 5, 1, IF(M17 = 4, 0.75, IF(M17 = 3, 0.5, IF(M17 = 2, 0.25, IF(M17 = 1, 0.05, IF(M17 = "<1%", 0.01, IF(M17 = "", ""))))))) | Q17: no | S17: =IF(R17 = 5, 1, IF(R17 = 4, 0.75, IF(R17 = 3, 0.5, IF(R17 = 2, 0.25, IF(R17 = 1, 0.05, IF(R17 = "<1%", 0.01, IF(R17 = "", ""))))))) | V17: yes | W17: 2 | X17: =IF(W17 = 5, 1, IF(W17 = 4, 0.75, IF(W17 = 3, 0.5, IF(W17 = 2, 0.25, IF(W17 = 1, 0.05, IF(W17 = "<1%", 0.01, IF(W17 = "", ""))))))) -> 0.25 | Z17: 2 | AA17: yes | AB17: 1 | AC17: =IF(AB17 = 5, 1, IF(AB17 = 4, 0.75, IF(AB17 = 3, 0.5, IF(AB17 = 2, 0.25, IF(AB17 = 1, 0.05, IF(AB17 = "<1%", 0.01, IF(AB17 = "", ""))))))) -> 0.05 | AE17: 1
A18: 15 | B18: mecaphesa asperata | C18: Northern Crab Spider | D18: Insect | Insecte | E18: Pink | F18: No | G18: no | I18: =IF(H18 = 5, 1, IF(H18 = 4, 0.75, IF(H18 = 3, 0.5, IF(H18 = 2, 0.25, IF(H18 = 1, 0.05, IF(H18 = "<1%", 0.01, IF(H18 = "", ""))))))) | L18: no | N18: =IF(M18 = 5, 1, IF(M18 = 4, 0.75, IF(M18 = 3, 0.5, IF(M18 = 2, 0.25, IF(M18 = 1, 0.05, IF(M18 = "<1%", 0.01, IF(M18 = "", ""))))))) | Q18: no | S18: =IF(R18 = 5, 1, IF(R18 = 4, 0.75, IF(R18 = 3, 0.5, IF(R18 = 2, 0.25, IF(R18 = 1, 0.05, IF(R18 = "<1%", 0.01, IF(R18 = "", ""))))))) | V18: yes | W18: 1 | X18: =IF(W18 = 5, 1, IF(W18 = 4, 0.75, IF(W18 = 3, 0.5, IF(W18 = 2, 0.25, IF(W18 = 1, 0.05, IF(W18 = "<1%", 0.01, IF(W18 = "", ""))))))) -> 0.05 | Z18: 1 | AA18: no | AC18: =IF(AB18 = 5, 1, IF(AB18 = 4, 0.75, IF(AB18 = 3, 0.5, IF(AB18 = 2, 0.25, IF(AB18 = 1, 0.05, IF(AB18 = "<1%", 0.01, IF(AB18 = "", "")))))))
A19: 16 | B19: Onoclea sensibilis | C19: Sensitive Fern | D19: Fern | Fougère | E19: Pink | F19: Yes | G19: yes | H19: 2 | I19: =IF(H19 = 5, 1, IF(H19 = 4, 0.75, IF(H19 = 3, 0.5, IF(H19 = 2, 0.25, IF(H19 = 1, 0.05, IF(H19 = "<1%", 0.01, IF(H19 = "", ""))))))) -> 0.25 | K19: 2 | L19: yes | M19: 4 | N19: =IF(M19 = 5, 1, IF(M19 = 4, 0.75, IF(M19 = 3, 0.5, IF(M19 = 2, 0.25, IF(M19 = 1, 0.05, IF(M19 = "<1%", 0.01, IF(M19 = "", ""))))))) -> 0.75 | P19: 2 | Q19: no | S19: =IF(R19 = 5, 1, IF(R19 = 4, 0.75, IF(R19 = 3, 0.5, IF(R19 = 2, 0.25, IF(R19 = 1, 0.05, IF(R19 = "<1%", 0.01, IF(R19 = "", ""))))))) | V19: yes | W19: 2 | X19: =IF(W19 = 5, 1, IF(W19 = 4, 0.75, IF(W19 = 3, 0.5, IF(W19 = 2, 0.25, IF(W19 = 1, 0.05, IF(W19 = "<1%", 0.01, IF(W19 = "", ""))))))) -> 0.25 | Z19: 1 | AA19: no | AC19: =IF(AB19 = 5, 1, IF(AB19 = 4, 0.75, IF(AB19 = 3, 0.5, IF(AB19 = 2, 0.25, IF(AB19 = 1, 0.05, IF(AB19 = "<1%", 0.01, IF(AB19 = "", "")))))))
A20: 17 | B20: Phalaris canariensis | C20: seed canary grass | D20: Grass or Sedge | Graminée | E20: Pink | F20: No | G20: no | I20: =IF(H20 = 5, 1, IF(H20 = 4, 0.75, IF(H20 = 3, 0.5, IF(H20 = 2, 0.25, IF(H20 = 1, 0.05, IF(H20 = "<1%", 0.01, IF(H20 = "", ""))))))) | L20: no | N20: =IF(M20 = 5, 1, IF(M20 = 4, 0.75, IF(M20 = 3, 0.5, IF(M20 = 2, 0.25, IF(M20 = 1, 0.05, IF(M20 = "<1%", 0.01, IF(M20 = "", ""))))))) | Q20: yes | R20: 4 | S20: =IF(R20 = 5, 1, IF(R20 = 4, 0.75, IF(R20 = 3, 0.5, IF(R20 = 2, 0.25, IF(R20 = 1, 0.05, IF(R20 = "<1%", 0.01, IF(R20 = "", ""))))))) -> 0.75 | U20: 2 | V20: yes | W20: 3 | X20: =IF(W20 = 5, 1, IF(W20 = 4, 0.75, IF(W20 = 3, 0.5, IF(W20 = 2, 0.25, IF(W20 = 1, 0.05, IF(W20 = "<1%", 0.01, IF(W20 = "", ""))))))) -> 0.5 | Z20: 2 | AA20: no | AC20: =IF(AB20 = 5, 1, IF(AB20 = 4, 0.75, IF(AB20 = 3, 0.5, IF(AB20 = 2, 0.25, IF(AB20 = 1, 0.05, IF(AB20 = "<1%", 0.01, IF(AB20 = "", "")))))))
A21: 18 | B21: poales | C21: Grass 1 | D21: Grass or Sedge | Graminée | E21: Pink | F21: No | G21: yes | H21: 3 | I21: =IF(H21 = 5, 1, IF(H21 = 4, 0.75, IF(H21 = 3, 0.5, IF(H21 = 2, 0.25, IF(H21 = 1, 0.05, IF(H21 = "<1%", 0.01, IF(H21 = "", ""))))))) -> 0.5 | K21: 1 | L21: no | N21: =IF(M21 = 5, 1, IF(M21 = 4, 0.75, IF(M21 = 3, 0.5, IF(M21 = 2, 0.25, IF(M21 = 1, 0.05, IF(M21 = "<1%", 0.01, IF(M21 = "", ""))))))) | Q21: no | S21: =IF(R21 = 5, 1, IF(R21 = 4, 0.75, IF(R21 = 3, 0.5, IF(R21 = 2, 0.25, IF(R21 = 1, 0.05, IF(R21 = "<1%", 0.01, IF(R21 = "", ""))))))) | X21: =IF(W21 = 5, 1, IF(W21 = 4, 0.75, IF(W21 = 3, 0.5, IF(W21 = 2, 0.25, IF(W21 = 1, 0.05, IF(W21 = "<1%", 0.01, IF(W21 = "", ""))))))) | AA21: yes | AB21: 3 | AC21: =IF(AB21 = 5, 1, IF(AB21 = 4, 0.75, IF(AB21 = 3, 0.5, IF(AB21 = 2, 0.25, IF(AB21 = 1, 0.05, IF(AB21 = "<1%", 0.01, IF(AB21 = "", ""))))))) -> 0.5 | AE21: 1
A22: 19 | B22: Prunus serotina | C22: black cherry | D22: Deciduous tree | Arbre décidu | E22: Pink | F22: Yes | G22: no | I22: =IF(H22 = 5, 1, IF(H22 = 4, 0.75, IF(H22 = 3, 0.5, IF(H22 = 2, 0.25, IF(H22 = 1, 0.05, IF(H22 = "<1%", 0.01, IF(H22 = "", ""))))))) | L22: no | N22: =IF(M22 = 5, 1, IF(M22 = 4, 0.75, IF(M22 = 3, 0.5, IF(M22 = 2, 0.25, IF(M22 = 1, 0.05, IF(M22 = "<1%", 0.01, IF(M22 = "", ""))))))) | Q22: yes | R22: 4 | S22: =IF(R22 = 5, 1, IF(R22 = 4, 0.75, IF(R22 = 3, 0.5, IF(R22 = 2, 0.25, IF(R22 = 1, 0.05, IF(R22 = "<1%", 0.01, IF(R22 = "", ""))))))) -> 0.75 | T22: BHD 40cm | U22: 1270 | X22: =IF(W22 = 5, 1, IF(W22 = 4, 0.75, IF(W22 = 3, 0.5, IF(W22 = 2, 0.25, IF(W22 = 1, 0.05, IF(W22 = "<1%", 0.01, IF(W22 = "", ""))))))) | AA22: no | AC22: =IF(AB22 = 5, 1, IF(AB22 = 4, 0.75, IF(AB22 = 3, 0.5, IF(AB22 = 2, 0.25, IF(AB22 = 1, 0.05, IF(AB22 = "<1%", 0.01, IF(AB22 = "", "")))))))
A23: 20 | B23: Prunus virginiana | C23: choke cherry | D23: Deciduous tree | Arbre décidu | E23: Pink | F23: Yes | G23: yes | H23: 1 | I23: =IF(H23 = 5, 1, IF(H23 = 4, 0.75, IF(H23 = 3, 0.5, IF(H23 = 2, 0.25, IF(H23 = 1, 0.05, IF(H23 = "<1%", 0.01, IF(H23 = "", ""))))))) -> 0.05 | J23: BHD 7cm | K23: 340 | L23: no | N23: =IF(M23 = 5, 1, IF(M23 = 4, 0.75, IF(M23 = 3, 0.5, IF(M23 = 2, 0.25, IF(M23 = 1, 0.05, IF(M23 = "<1%", 0.01, IF(M23 = "", ""))))))) | O23: BHD 22cm | Q23: no | S23: =IF(R23 = 5, 1, IF(R23 = 4, 0.75, IF(R23 = 3, 0.5, IF(R23 = 2, 0.25, IF(R23 = 1, 0.05, IF(R23 = "<1%", 0.01, IF(R23 = "", ""))))))) | X23: =IF(W23 = 5, 1, IF(W23 = 4, 0.75, IF(W23 = 3, 0.5, IF(W23 = 2, 0.25, IF(W23 = 1, 0.05, IF(W23 = "<1%", 0.01, IF(W23 = "", ""))))))) | AA23: no | AC23: =IF(AB23 = 5, 1, IF(AB23 = 4, 0.75, IF(AB23 = 3, 0.5, IF(AB23 = 2, 0.25, IF(AB23 = 1, 0.05, IF(AB23 = "<1%", 0.01, IF(AB23 = "", "")))))))
A24: 21 | B24: Solidago | C24: Golden Rod | D24: Grass or Sedge | Graminée | E24: Pink | F24: Yes | G24: no | I24: =IF(H24 = 5, 1, IF(H24 = 4, 0.75, IF(H24 = 3, 0.5, IF(H24 = 2, 0.25, IF(H24 = 1, 0.05, IF(H24 = "<1%", 0.01, IF(H24 = "", ""))))))) | L24: no | N24: =IF(M24 = 5, 1, IF(M24 = 4, 0.75, IF(M24 = 3, 0.5, IF(M24 = 2, 0.25, IF(M24 = 1, 0.05, IF(M24 = "<1%", 0.01, IF(M24 = "", ""))))))) | Q24: no | S24: =IF(R24 = 5, 1, IF(R24 = 4, 0.75, IF(R24 = 3, 0.5, IF(R24 = 2, 0.25, IF(R24 = 1, 0.05, IF(R24 = "<1%", 0.01, IF(R24 = "", ""))))))) | X24: =IF(W24 = 5, 1, IF(W24 = 4, 0.75, IF(W24 = 3, 0.5, IF(W24 = 2, 0.25, IF(W24 = 1, 0.05, IF(W24 = "<1%", 0.01, IF(W24 = "", ""))))))) | AA24: yes | AB24: 2 | AC24: =IF(AB24 = 5, 1, IF(AB24 = 4, 0.75, IF(AB24 = 3, 0.5, IF(AB24 = 2, 0.25, IF(AB24 = 1, 0.05, IF(AB24 = "<1%", 0.01, IF(AB24 = "", ""))))))) -> 0.25 | AE24: 3
A25: 22 | B25: Tamias | C25: Chipmunks | D25: Insect | Insecte | E25: Pink | F25: No | G25: yes | I25: =IF(H25 = 5, 1, IF(H25 = 4, 0.75, IF(H25 = 3, 0.5, IF(H25 = 2, 0.25, IF(H25 = 1, 0.05, IF(H25 = "<1%", 0.01, IF(H25 = "", ""))))))) | L25: no | N25: =IF(M25 = 5, 1, IF(M25 = 4, 0.75, IF(M25 = 3, 0.5, IF(M25 = 2, 0.25, IF(M25 = 1, 0.05, IF(M25 = "<1%", 0.01, IF(M25 = "", ""))))))) | Q25: no | S25: =IF(R25 = 5, 1, IF(R25 = 4, 0.75, IF(R25 = 3, 0.5, IF(R25 = 2, 0.25, IF(R25 = 1, 0.05, IF(R25 = "<1%", 0.01, IF(R25 = "", ""))))))) | X25: =IF(W25 = 5, 1, IF(W25 = 4, 0.75, IF(W25 = 3, 0.5, IF(W25 = 2, 0.25, IF(W25 = 1, 0.05, IF(W25 = "<1%", 0.01, IF(W25 = "", ""))))))) | AA25: no | AC25: =IF(AB25 = 5, 1, IF(AB25 = 4, 0.75, IF(AB25 = 3, 0.5, IF(AB25 = 2, 0.25, IF(AB25 = 1, 0.05, IF(AB25 = "<1%", 0.01, IF(AB25 = "", "")))))))
A26: 23 | B26: Acer rubrum | C26: Red Maple | D26: Deciduous tree | Arbre décidu | E26: Purple | F26: Yes | G26: Yes | H26: 5 | I26: =IF(H26 = 5, 1, IF(H26 = 4, 0.75, IF(H26 = 3, 0.5, IF(H26 = 2, 0.25, IF(H26 = 1, 0.05, IF(H26 = "<1%", 0.01, IF(H26 = "", ""))))))) -> 1 | J26: 1, 3, Ca | K26: 1000 to 2000 | L26: Yes | M26: 1 | N26: =IF(M26 = 5, 1, IF(M26 = 4, 0.75, IF(M26 = 3, 0.5, IF(M26 = 2, 0.25, IF(M26 = 1, 0.05, IF(M26 = "<1%", 0.01, IF(M26 = "", ""))))))) -> 0.05 | O26: 1, 5, SD | P26: 0 to 10 | Q26: Yes | R26: 4 | S26: =IF(R26 = 5, 1, IF(R26 = 4, 0.75, IF(R26 = 3, 0.5, IF(R26 = 2, 0.25, IF(R26 = 1, 0.05, IF(R26 = "<1%", 0.01, IF(R26 = "", ""))))))) -> 0.75 | T26: 1, 5, SD + Ca | U26: 10 to 2000 | V26: Yes | W26: 5 | X26: =IF(W26 = 5, 1, IF(W26 = 4, 0.75, IF(W26 = 3, 0.5, IF(W26 = 2, 0.25, IF(W26 = 1, 0.05, IF(W26 = "<1%", 0.01, IF(W26 = "", ""))))))) -> 1 | Y26: 1, 5, Ca | Z26: 1000 to 2000 | AA26: Yes | AB26: 5 | AC26: =IF(AB26 = 5, 1, IF(AB26 = 4, 0.75, IF(AB26 = 3, 0.5, IF(AB26 = 2, 0.25, IF(AB26 = 1, 0.05, IF(AB26 = "<1%", 0.01, IF(AB26 = "", ""))))))) -> 1 | AD26: 1, 5, SD + Ca | AE26: 10 to 2000
A27: 24 | B27: Acer sp. | C27: Maple | D27: Deciduous tree | Arbre décidu | E27: Purple | F27: Yes | G27: No | I27: =IF(H27 = 5, 1, IF(H27 = 4, 0.75, IF(H27 = 3, 0.5, IF(H27 = 2, 0.25, IF(H27 = 1, 0.05, IF(H27 = "<1%", 0.01, IF(H27 = "", ""))))))) | L27: Yes | M27: 1 | N27: =IF(M27 = 5, 1, IF(M27 = 4, 0.75, IF(M27 = 3, 0.5, IF(M27 = 2, 0.25, IF(M27 = 1, 0.05, IF(M27 = "<1%", 0.01, IF(M27 = "", ""))))))) -> 0.05 | O27: 1, 5, SD | P27: 0 to 10 | Q27: Yes | R27: 1 | S27: =IF(R27 = 5, 1, IF(R27 = 4, 0.75, IF(R27 = 3, 0.5, IF(R27 = 2, 0.25, IF(R27 = 1, 0.05, IF(R27 = "<1%", 0.01, IF(R27 = "", ""))))))) -> 0.05 | T27: 1, 5, SD | U27: 0 to 10 | V27: No | X27: =IF(W27 = 5, 1, IF(W27 = 4, 0.75, IF(W27 = 3, 0.5, IF(W27 = 2, 0.25, IF(W27 = 1, 0.05, IF(W27 = "<1%", 0.01, IF(W27 = "", ""))))))) | AA27: No | AC27: =IF(AB27 = 5, 1, IF(AB27 = 4, 0.75, IF(AB27 = 3, 0.5, IF(AB27 = 2, 0.25, IF(AB27 = 1, 0.05, IF(AB27 = "<1%", 0.01, IF(AB27 = "", "")))))))
A28: 25 | B28: Cornus alternifolia | C28: Alternate-leaved Dogwood | D28: Shrub | Arbuste | E28: Purple | F28: No | G28: No | I28: =IF(H28 = 5, 1, IF(H28 = 4, 0.75, IF(H28 = 3, 0.5, IF(H28 = 2, 0.25, IF(H28 = 1, 0.05, IF(H28 = "<1%", 0.01, IF(H28 = "", ""))))))) | L28: No | N28: =IF(M28 = 5, 1, IF(M28 = 4, 0.75, IF(M28 = 3, 0.5, IF(M28 = 2, 0.25, IF(M28 = 1, 0.05, IF(M28 = "<1%", 0.01, IF(M28 = "", ""))))))) | Q28: Yes | R28: 1 | S28: =IF(R28 = 5, 1, IF(R28 = 4, 0.75, IF(R28 = 3, 0.5, IF(R28 = 2, 0.25, IF(R28 = 1, 0.05, IF(R28 = "<1%", 0.01, IF(R28 = "", ""))))))) -> 0.05 | T28: 1,7, SD | U28: 10 to 50 | V28: No | X28: =IF(W28 = 5, 1, IF(W28 = 4, 0.75, IF(W28 = 3, 0.5, IF(W28 = 2, 0.25, IF(W28 = 1, 0.05, IF(W28 = "<1%", 0.01, IF(W28 = "", ""))))))) | AA28: No | AC28: =IF(AB28 = 5, 1, IF(AB28 = 4, 0.75, IF(AB28 = 3, 0.5, IF(AB28 = 2, 0.25, IF(AB28 = 1, 0.05, IF(AB28 = "<1%", 0.01, IF(AB28 = "", "")))))))
A29: 26 | B29: Doellingeria umbellata | C29: Flat-top White Aster | D29: Grass or Sedge | Graminée | E29: Purple | F29: Yes | G29: No | I29: =IF(H29 = 5, 1, IF(H29 = 4, 0.75, IF(H29 = 3, 0.5, IF(H29 = 2, 0.25, IF(H29 = 1, 0.05, IF(H29 = "<1%", 0.01, IF(H29 = "", ""))))))) | L29: No | N29: =IF(M29 = 5, 1, IF(M29 = 4, 0.75, IF(M29 = 3, 0.5, IF(M29 = 2, 0.25, IF(M29 = 1, 0.05, IF(M29 = "<1%", 0.01, IF(M29 = "", ""))))))) | Q29: No | S29: =IF(R29 = 5, 1, IF(R29 = 4, 0.75, IF(R29 = 3, 0.5, IF(R29 = 2, 0.25, IF(R29 = 1, 0.05, IF(R29 = "<1%", 0.01, IF(R29 = "", ""))))))) | V29: Yes | W29: 1 | X29: =IF(W29 = 5, 1, IF(W29 = 4, 0.75, IF(W29 = 3, 0.5, IF(W29 = 2, 0.25, IF(W29 = 1, 0.05, IF(W29 = "<1%", 0.01, IF(W29 = "", ""))))))) -> 0.05 | Y29: 1,7, SD | Z29: 50 to 200 | AA29: No | AC29: =IF(AB29 = 5, 1, IF(AB29 = 4, 0.75, IF(AB29 = 3, 0.5, IF(AB29 = 2, 0.25, IF(AB29 = 1, 0.05, IF(AB29 = "<1%", 0.01, IF(AB29 = "", "")))))))
A30: 27 | B30: Frangula sp. | C30: False-Buckthorns | D30: Deciduous tree | Arbre décidu | E30: Purple | F30: No | G30: Yes | H30: 2 | I30: =IF(H30 = 5, 1, IF(H30 = 4, 0.75, IF(H30 = 3, 0.5, IF(H30 = 2, 0.25, IF(H30 = 1, 0.05, IF(H30 = "<1%", 0.01, IF(H30 = "", ""))))))) -> 0.25 | J30: 1, 5, SD | K30: 10 to 50 | L30: Yes | M30: 2 | N30: =IF(M30 = 5, 1, IF(M30 = 4, 0.75, IF(M30 = 3, 0.5, IF(M30 = 2, 0.25, IF(M30 = 1, 0.05, IF(M30 = "<1%", 0.01, IF(M30 = "", ""))))))) -> 0.25 | O30: 1, 5, SD, FR | P30: 10 to 500 | Q30: No | S30: =IF(R30 = 5, 1, IF(R30 = 4, 0.75, IF(R30 = 3, 0.5, IF(R30 = 2, 0.25, IF(R30 = 1, 0.05, IF(R30 = "<1%", 0.01, IF(R30 = "", ""))))))) | V30: Yes | W30: 4 | X30: =IF(W30 = 5, 1, IF(W30 = 4, 0.75, IF(W30 = 3, 0.5, IF(W30 = 2, 0.25, IF(W30 = 1, 0.05, IF(W30 = "<1%", 0.01, IF(W30 = "", ""))))))) -> 0.75 | Y30: 1, 5 | Z30: 50 to 200 | AA30: Yes | AB30: 2 | AC30: =IF(AB30 = 5, 1, IF(AB30 = 4, 0.75, IF(AB30 = 3, 0.5, IF(AB30 = 2, 0.25, IF(AB30 = 1, 0.05, IF(AB30 = "<1%", 0.01, IF(AB30 = "", ""))))))) -> 0.25 | AD30: 1, 5 | AE30: 50 to 200
A31: 28 | B31: Prunus serotina | C31: Black Cherry | D31: Deciduous tree | Arbre décidu | E31: Purple | F31: Yes | G31: No | I31: =IF(H31 = 5, 1, IF(H31 = 4, 0.75, IF(H31 = 3, 0.5, IF(H31 = 2, 0.25, IF(H31 = 1, 0.05, IF(H31 = "<1%", 0.01, IF(H31 = "", ""))))))) | L31: No | N31: =IF(M31 = 5, 1, IF(M31 = 4, 0.75, IF(M31 = 3, 0.5, IF(M31 = 2, 0.25, IF(M31 = 1, 0.05, IF(M31 = "<1%", 0.01, IF(M31 = "", ""))))))) | Q31: Yes | R31: 1 | S31: =IF(R31 = 5, 1, IF(R31 = 4, 0.75, IF(R31 = 3, 0.5, IF(R31 = 2, 0.25, IF(R31 = 1, 0.05, IF(R31 = "<1%", 0.01, IF(R31 = "", ""))))))) -> 0.05 | T31: 1,7, SD | U31: 11 to 50 | V31: No | X31: =IF(W31 = 5, 1, IF(W31 = 4, 0.75, IF(W31 = 3, 0.5, IF(W31 = 2, 0.25, IF(W31 = 1, 0.05, IF(W31 = "<1%", 0.01, IF(W31 = "", ""))))))) | AA31: No | AC31: =IF(AB31 = 5, 1, IF(AB31 = 4, 0.75, IF(AB31 = 3, 0.5, IF(AB31 = 2, 0.25, IF(AB31 = 1, 0.05, IF(AB31 = "<1%", 0.01, IF(AB31 = "", "")))))))
A32: 29 | B32: Prunus sp. | C32: Plums, Cherries, and Allies | D32: Shrub | Arbuste | E32: Purple | F32: Yes | G32: No | I32: =IF(H32 = 5, 1, IF(H32 = 4, 0.75, IF(H32 = 3, 0.5, IF(H32 = 2, 0.25, IF(H32 = 1, 0.05, IF(H32 = "<1%", 0.01, IF(H32 = "", ""))))))) | L32: No | N32: =IF(M32 = 5, 1, IF(M32 = 4, 0.75, IF(M32 = 3, 0.5, IF(M32 = 2, 0.25, IF(M32 = 1, 0.05, IF(M32 = "<1%", 0.01, IF(M32 = "", ""))))))) | Q32: Yes | R32: 1 | S32: =IF(R32 = 5, 1, IF(R32 = 4, 0.75, IF(R32 = 3, 0.5, IF(R32 = 2, 0.25, IF(R32 = 1, 0.05, IF(R32 = "<1%", 0.01, IF(R32 = "", ""))))))) -> 0.05 | T32: 1,7, SD | U32: 12 to 50 | V32: No | X32: =IF(W32 = 5, 1, IF(W32 = 4, 0.75, IF(W32 = 3, 0.5, IF(W32 = 2, 0.25, IF(W32 = 1, 0.05, IF(W32 = "<1%", 0.01, IF(W32 = "", ""))))))) | AA32: No | AC32: =IF(AB32 = 5, 1, IF(AB32 = 4, 0.75, IF(AB32 = 3, 0.5, IF(AB32 = 2, 0.25, IF(AB32 = 1, 0.05, IF(AB32 = "<1%", 0.01, IF(AB32 = "", "")))))))
A33: 30 | B33: Spiraea sp. | C33: Meadowsweets | D33: Deciduous tree | Arbre décidu | E33: Purple | F33: No | G33: No | I33: =IF(H33 = 5, 1, IF(H33 = 4, 0.75, IF(H33 = 3, 0.5, IF(H33 = 2, 0.25, IF(H33 = 1, 0.05, IF(H33 = "<1%", 0.01, IF(H33 = "", ""))))))) | L33: Yes | M33: 3 | N33: =IF(M33 = 5, 1, IF(M33 = 4, 0.75, IF(M33 = 3, 0.5, IF(M33 = 2, 0.25, IF(M33 = 1, 0.05, IF(M33 = "<1%", 0.01, IF(M33 = "", ""))))))) -> 0.5 | O33: 1,7 | P33: 10 to 50 | Q33: No | S33: =IF(R33 = 5, 1, IF(R33 = 4, 0.75, IF(R33 = 3, 0.5, IF(R33 = 2, 0.25, IF(R33 = 1, 0.05, IF(R33 = "<1%", 0.01, IF(R33 = "", ""))))))) | V33: No | X33: =IF(W33 = 5, 1, IF(W33 = 4, 0.75, IF(W33 = 3, 0.5, IF(W33 = 2, 0.25, IF(W33 = 1, 0.05, IF(W33 = "<1%", 0.01, IF(W33 = "", ""))))))) | AA33: No | AC33: =IF(AB33 = 5, 1, IF(AB33 = 4, 0.75, IF(AB33 = 3, 0.5, IF(AB33 = 2, 0.25, IF(AB33 = 1, 0.05, IF(AB33 = "<1%", 0.01, IF(AB33 = "", "")))))))
A34: 31 | B34: Tilia sp. | C34: Lindens, Basswoods, and Lime Trees | D34: Deciduous tree | Arbre décidu | E34: Purple | F34: No | G34: No | I34: =IF(H34 = 5, 1, IF(H34 = 4, 0.75, IF(H34 = 3, 0.5, IF(H34 = 2, 0.25, IF(H34 = 1, 0.05, IF(H34 = "<1%", 0.01, IF(H34 = "", ""))))))) | L34: Yes | M34: 1 | N34: =IF(M34 = 5, 1, IF(M34 = 4, 0.75, IF(M34 = 3, 0.5, IF(M34 = 2, 0.25, IF(M34 = 1, 0.05, IF(M34 = "<1%", 0.01, IF(M34 = "", ""))))))) -> 0.05 | O34: 1,5, SD | P34: 0 to 10 | Q34: No | S34: =IF(R34 = 5, 1, IF(R34 = 4, 0.75, IF(R34 = 3, 0.5, IF(R34 = 2, 0.25, IF(R34 = 1, 0.05, IF(R34 = "<1%", 0.01, IF(R34 = "", ""))))))) | V34: No | X34: =IF(W34 = 5, 1, IF(W34 = 4, 0.75, IF(W34 = 3, 0.5, IF(W34 = 2, 0.25, IF(W34 = 1, 0.05, IF(W34 = "<1%", 0.01, IF(W34 = "", ""))))))) | AA34: No | AC34: =IF(AB34 = 5, 1, IF(AB34 = 4, 0.75, IF(AB34 = 3, 0.5, IF(AB34 = 2, 0.25, IF(AB34 = 1, 0.05, IF(AB34 = "<1%", 0.01, IF(AB34 = "", "")))))))
A35: 32 | B35: Ageratina aromatica | C35: White snakeroot | D35: Grass or Sedge | Graminée | E35: Yellow | F35: No | G35: No | I35: =IF(H35 = 5, 1, IF(H35 = 4, 0.75, IF(H35 = 3, 0.5, IF(H35 = 2, 0.25, IF(H35 = 1, 0.05, IF(H35 = "<1%", 0.01, IF(H35 = "", ""))))))) | L35: No | N35: =IF(M35 = 5, 1, IF(M35 = 4, 0.75, IF(M35 = 3, 0.5, IF(M35 = 2, 0.25, IF(M35 = 1, 0.05, IF(M35 = "<1%", 0.01, IF(M35 = "", ""))))))) | Q35: No | S35: =IF(R35 = 5, 1, IF(R35 = 4, 0.75, IF(R35 = 3, 0.5, IF(R35 = 2, 0.25, IF(R35 = 1, 0.05, IF(R35 = "<1%", 0.01, IF(R35 = "", ""))))))) | V35: Yes | W35: 2 | X35: =IF(W35 = 5, 1, IF(W35 = 4, 0.75, IF(W35 = 3, 0.5, IF(W35 = 2, 0.25, IF(W35 = 1, 0.05, IF(W35 = "<1%", 0.01, IF(W35 = "", ""))))))) -> 0.25 | Z35: between 50 and 200 | AC35: =IF(AB35 = 5, 1, IF(AB35 = 4, 0.75, IF(AB35 = 3, 0.5, IF(AB35 = 2, 0.25, IF(AB35 = 1, 0.05, IF(AB35 = "<1%", 0.01, IF(AB35 = "", "")))))))
